Workbook
Name _._?__?h_?: '[1]6월인원'!#REF!
Name _._?__?h_?: '[1]6월인원'!#REF!
Name _._?__?h_?: '[1]6월인원'!#REF!
Name _._?__?h_?: '[1]6월인원'!#REF!
Name __: '[2]95TOTREV'!#REF!
Name __: '[2]95TOTREV'!#REF!
Name __: '[2]95TOTREV'!#REF!
Name __: '[2]95TOTREV'!#REF!
Name _1: #REF!
Name _1: #REF!
Name _1: #REF!
Name _1: #REF!
Name _2: #REF!
Name _2: #REF!
Name _2: #REF!
Name _2: #REF!
Name _3: #REF!
Name _3: #REF!
Name _3: #REF!
Name _3: #REF!
Name _AMT13300: #REF!
Name _AMT13300: #REF!
Name _AMT13300: #REF!
Name _AMT13300: #REF!
Name _AMT13502: #REF!
Name _AMT13502: #REF!
Name _AMT13502: #REF!
Name _AMT13502: #REF!
Name _AMT41301: #REF!
Name _AMT41301: #REF!
Name _AMT41301: #REF!
Name _AMT41301: #REF!
Name _AMT85116: #REF!
Name _AMT85116: #REF!
Name _AMT85116: #REF!
Name _AMT85116: #REF!
Name _AMT85125: #REF!
Name _AMT85125: #REF!
Name _AMT85125: #REF!
Name _AMT85125: #REF!
Name _AMT86106: #REF!
Name _AMT86106: #REF!
Name _AMT86106: #REF!
Name _AMT86106: #REF!
Name _EXC2: #REF!
Name _EXC2: #REF!
Name _EXC2: #REF!
Name _EXC2: #REF!
Name _Mr0301: [10]장비명!$F$5
Name _Mr0401: [10]장비명!$F$9
Name _Mr05: [10]장비명!$F$20
Name _Mr0502: [11]장비명!$F$44
Name _Mr0601: [10]장비명!$F$41
Name _Mr07: [10]장비명!$F$27
Name _Mr0901: [10]장비명!$F$30
Name _Mr0902: [10]장비명!$F$31
Name _Mr0903: [10]장비명!$F$32
Name _Mr11: [10]장비명!$F$67
Name _Mr14: [10]장비명!$F$61
Name _Mr1502: [10]장비명!$F$79

Sheet 대기+수처리+헝가리
B2: 영업3팀 (대기+수처리+헝가리법인)
B4: 3. '26년 계획대비 차이
B5: 구분 | C5: '26년 계획(A) | K5: '26년 예상(B) | S5: 차이 B-A
C6: 대기 | E6: 수처리 | G6: 헝가리법인 | I6: 함계 | K6: 대기 | M6: 수처리 | O6: 헝가리법인 | Q6: 함계 | S6: 대기 | U6: 수처리 | W6: 헝가리법인 | Y6: 함계
B7: '26년 매출반영 | C7: 44247000000 | D7: =C7/C$7 -> 1 | E7: 1.698249e+10 | F7: =E7/E$7 -> 1 | I7: =C7+E7+G7 -> 6.122949e+10 | J7: =I7/I$7 -> 1 | K7: =대기!E42 -> 67373686852 | L7: =K7/K$7 -> 1 | M7: =수처리!E42 -> 16339092620 | N7: =M7/M$7 -> 1 | Q7: =K7+M7+O7 -> 83712779472 | R7: =Q7/Q$7 -> 1 | S7: =K7-C7 -> 23126686852 | T7: =Q7/I7-1 -> 0.36719706 | U7: =M7-E7 -> -6.4339775e+08 | V7: =U7/U$7 -> 1 | Y7: =S7+U7+W7 -> 2.2483289e+10 | Z7: =K7/C7-1 -> 0.52267243
B8: '26년 제조간접원가 | C8: =C7*D8 -> 2.4322972e+09 | D8: 0.054970896 | E8: =E7*F8 -> 1.2567043e+09 | F8: 0.074 | I8: =G8+E8+C8 -> 3.6890015e+09 | J8: 0.054970896 | K8: =대기!E43 -> 3.5673845e+09 | L8: =K8/K7 -> 0.052949225 | M8: =수처리!E43 -> 9.7707352e+08 | N8: =M8/M7 -> 0.059799742 | Q8: =O8+M8+K8 -> 4.544458e+09 | R8: 0.054970896 | S8: =K8-C8 -> 1.1350873e+09 | T8: =Q8/I8-1 -> 0.23189379 | U8: =M8-E8 -> -2.7963076e+08 | V8: 0.054970896 | Y8: =W8+U8+S8 -> 8.5545652e+08 | Z8: =K8/C8-1 -> 0.46667294
B9: '26년 제조원가 | C9: 3.9639494e+10 | D9: =C9/C$7 -> 0.89586851 | E9: 1.5145215e+10 | F9: =E9/E$7 -> 0.89181357 | I9: =C9+E9+G9 -> 5.4784709e+10 | J9: =I9/I$7 -> 0.89474384 | K9: =대기!E44 -> 6.1121339e+10 | L9: =K9/K$7 -> 0.90719896 | M9: =수처리!E44 -> 1.4668117e+10 | N9: =M9/M$7 -> 0.89773145 | Q9: =K9+M9+O9 -> 7.5789456e+10 | R9: =Q9/Q$7 -> 0.90535109 | S9: =K9-C9 -> 2.1481845e+10 | T9: =Q9/I9-1 -> 0.38340527 | U9: =M9-E9 -> -4.7709801e+08 | V9: =U9/U$7 -> 0.74152887 | Y9: =S9+U9+W9 -> 2.1004747e+10 | Z9: =K9/C9-1 -> 0.54193034
B10: '26년 매출총이익 | C10: =C7-C9 -> 4.6075058e+09 | D10: =C10/C$7 -> 0.10413149 | E10: =E7-E9 -> 1.8372751e+09 | F10: =E10/E$7 -> 0.10818643 | I10: =C10+E10+G10 -> 6.4447809e+09 | J10: =I10/I$7 -> 0.10525616 | K10: =대기!E45 -> 6.2523481e+09 | L10: =K10/K$7 -> 0.092801039 | M10: =수처리!E45 -> 1.6709753e+09 | N10: =M10/M$7 -> 0.10226855 | Q10: =K10+M10+O10 -> 7.9233235e+09 | R10: =Q10/Q$7 -> 0.094648912 | S10: =K10-C10 -> 1.6448423e+09 | T10: =Q10/I10-1 -> 0.22941704 | U10: =M10-E10 -> -1.6629974e+08 | V10: =U10/U$7 -> 0.25847113 | Y10: =S10+U10+W10 -> 1.4785426e+09 | Z10: =K10/C10-1 -> 0.35699191
B11: '26년 판관비( C) | C11: =C7*D11 -> 5442381000 | D11: 0.123 | E11: =E7*F11 -> 2.2756537e+09 | F11: 0.134 | I11: =C11+E11+G11 -> 7.7180347e+09 | J11: 0.123 | K11: =대기!E46 -> 8.2869635e+09 | L11: =K11/K7 -> 0.123 | M11: =수처리!E46 -> 2.1894384e+09 | N11: =M11/M7 -> 0.134 | Q11: =K11+M11+O11 -> 1.0476402e+10 | R11: 0.123 | S11: =K11-C11 -> 2.8445825e+09 | T11: =Q11/I11-1 -> 0.35739243 | U11: =M11-E11 -> -86215299 | V11: 0.123 | Y11: =S11+U11+W11 -> 2.7583672e+09 | Z11: =K11/C11-1 -> 0.52267243
B12: '26년 영업이익( D) | C12: =C7-C9-C11 -> -8.3487517e+08 | D12: =C12/C$7 -> -0.018868515 | E12: =E7-E9-E11 -> -4.3837863e+08 | F12: =E12/E$7 -> -0.025813566 | G12: =G7-G9-G11 -> 0 | I12: =C12+E12+G12 -> -1.2732538e+09 | J12: =I12/I$7 -> -0.02079478 | K12: =대기!E47 -> -2.0346153e+09 | L12: =K12/K$7 -> -0.030198961 | M12: =수처리!E47 -> -5.1846308e+08 | N12: =M12/M$7 -> -0.031731449 | Q12: =K12+M12+O12 -> -2.5530784e+09 | R12: =Q12/Q$7 -> -0.030498073 | S12: =K12-C12 -> -1.1997402e+09 | T12: =Q12/I12-1 -> 1.0051606 | U12: =M12-E12 -> -80084445 | V12: =U12/U$7 -> 0.12447113 | Y12: =S12+U12+W12 -> -1.2798246e+09 | Z12: =K12/C12-1 -> 1.4370294
B13: 손익분기 판관비 부담 (C+D, 영업이익 < 0) | C13: =C11+C12 -> 4.6075058e+09 | E13: =E11+E12 -> 1.8372751e+09 | G13: =G11+G12 -> 0 | I13: =I11+I12 -> 6.4447809e+09 | K13: =K11+K12 -> 6.2523481e+09 | M13: =수처리!E48 -> 1.6709753e+09 | Q13: =Q11+Q12 -> 7.9233235e+09 | S13: =K13-C13 -> 1.6448423e+09 | U13: =M13-E13 -> -1.6629974e+08 | W13: =W11+W12 -> 0 | Y13: =Y11+Y12 -> 1.4785426e+09
B15: '26년 증분이익 | C15: =C13+C8 -> 7.039803e+09 | E15: =E8+E13 -> 3.0939794e+09 | G15: =G13+G8 -> 0 | I15: =I13+I8 -> 1.0133782e+10 | K15: =K13+K8 -> 9.8197326e+09 | M15: =M13+M8 -> 2.6480489e+09 | O15: =O13+O8 -> 0 | Q15: =Q13+Q8 -> 1.2467781e+10 | S15: =S13+S8 -> 2.7799296e+09 | U15: =U13+U8 -> -4.4593051e+08 | W15: =W13+W8 -> 0 | Y15: =Y13+Y8 -> 2.3339991e+09
Y16: =Y15/Q7 -> 0.027881037

Sheet 대기
B2: 대기방지
C4: '25년 수주잔고 => | Z4: '26년 수주 =>
B5: 1. 프로젝트별 세부내역 | C5: PASC0IB20250011 | E5: PABF0IK20250011 | G5: PABF1IE20230011 | I5: PASC0IT20250011 | K5: PAAC0IE20250011 | M5: PAAE0IC20230011 | O5: PASC0IB20240011 | Q5: PACC0EK20050011 | S5: PAAE0IE20250011 | U5: PADH0IE20250011 | W5: PASC0IP20220011 | BM5: (단위 : 원/VAT별도)
B6: 구분 | C6: BHI / QATAR FACILITY E IWPP SCR SYSTEM | E6: KTC / EV용 화재안전성센터 대방설비 설치공사 | G6: BM HU / [EA1] 환경설비 납품, 설치 및 시운전 공사 | I6: 통영에코파워 / HRSG #11, #12 SCR 환원제 직접 분사 설비 설치 공사 | K6: 에코프로머티리얼즈 / [4캠퍼스] CPM3 SCRUBBER 납품 및 설치공사 | M6: CGN대산전력 / Air Pollution Control System 공급 및 설치계약 | O6: 비에이치아이 / Amiral Cogen IPP PJT/SCR/YPES (HG) | Q6: 광림 / 특장도장동 환경설비 연간유지보수 | S6: 에코프로비엠 / 고체전해질PP 라인 대기오염방지설비 소음기 설치 건 | U6: 에코프로비엠 / 오창 환경사업장 3F 제습 설비 보완 공사 | W6: 포스코 / (포항)1전강 2COF SCR 신설(설비단독,내자) 외 1건 | Z6: BHI 대만 튱샤오 HRSG SCR PKG | AB6: KCL(삼척) 화재센터 ACT | AD6: 에코프로INNO HU LHM8K IPPC | AF6: 도레이첨단소재(구미) BF+SCR | AH6: BHI 포스코(포항) LNG복합 | AJ6: 유한화학(화성) RTO 신규 | AL6: 삼천포발전본부 SCR 개선 | AN6: 한국소방산업기술원 환경설비 | AP6: 한주(울산)_SCR | AR6: 동서발전(음성) #2 복합발전 | AT6: 와이엔텍(여수) | AV6: 삼표시멘트(삼척) | AX6: 여주축협(여주) | AZ6: 중부발전(용인) | BB6: LG화학(여수) | BD6: 동서발전(여수) | BF6: 오성테크놀로지(익산) | BH6: 금강씨엔티(동해) | BJ6: 북산환경(안산) | BL6: 합 계
B7: 계약예정일 | C7: 25년 6월 - 26년 6월 | E7: 25년 6월 - 26년 9월 | G7: 23년 2월 - 26년 12월 | I7: 25년 10월 - 26년 4월 | K7: 25년 8월 - 26년 5월 | M7: 23년 11월 - 26년 9월 | O7: 24년 10월 - 25년 9월 | Q7: 25년 5월 - 26년 4월 | S7: 25년 11월 - 26년 1월 | U7: 25년 8월 - 25년 11월 | W7: 22년 8월 - 25년 1월 | Z7: 26년 3월 | AB7: 26년 2월 | AD7: 26년 2월 | AF7: 26년 3월 | AH7: 26년 4월 | AJ7: 26년 4월 | AL7: 26년 5월 | AN7: 26년 7월 | AP7: 26년 10월 | AR7: 26년 9월 | AT7: 26년 10월 | AV7: 26년 9월 | AX7: 26년 9월 | AZ7: 26년 10월 | BB7: 26년 10월 | BD7: 26년 10월 | BF7: 26년 9월 | BH7: 26년 4월 | BJ7: 26년 7월
B8: 계약예정금액 | C8: 2741193600 | D8: =C8/C$8 -> 1 | E8: 1793293440 | F8: =E8/E$8 -> 1 | G8: 1232485613 | H8: =G8/G$8 -> 1 | I8: 782283637 | J8: =I8/I$8 -> 1 | K8: 407388150 | L8: =K8/K$8 -> 1 | M8: 161695500 | N8: =M8/M$8 -> 1 | O8: 118000000 | P8: =O8/O$8 -> 1 | Q8: 40900000 | R8: =Q8/Q$8 -> 1 | S8: 32000000 | T8: =S8/S$8 -> 1 | U8: 30516912 | V8: =U8/U$8 -> 1 | W8: 8730000 | X8: =W8/W$8 -> 1 | Z8: 23350000000 | AA8: =Z8/Z$8 -> 1 | AB8: 4000000000 | AC8: =AB8/AB$8 -> 1 | AD8: 374550000 | AE8: =AD8/AD$8 -> 1 | AF8: 3200000000 | AG8: =AF8/AF$8 -> 1 | AH8: =4400000000+AH17 -> 7386500000 | AI8: =AH8/AH$8 -> 1 | AJ8: 3990000000 | AK8: =AJ8/AJ$8 -> 1 | AL8: 2460000000 | AM8: =AL8/AL$8 -> 1 | AN8: 1629000000 | AO8: =AN8/AN$8 -> 1 | AP8: 3000000000 | AQ8: =AP8/AP$8 -> 1 | AR8: 8000000000 | AS8: =AR8/AR$8 -> 1 | AT8: 30000000000 | AU8: =AT8/AT$8 -> 1 | AV8: 15000000000 | AW8: =AV8/AV$8 -> 1 | AX8: 44000000000 | AY8: =AX8/AX$8 -> 1 | AZ8: 19000000000 | BA8: =AZ8/AZ$8 -> 1 | BB8: 2500000000 | BC8: =BB8/BB$8 -> 1 | BD8: 19000000000 | BE8: =BD8/BD$8 -> 1 | BF8: 4000000000 | BG8: =BF8/BF$8 -> 1 | BH8: 1000000000 | BI8: =BH8/BH$8 -> 1 | BJ8: 20000000000 | BK8: =BJ8/BJ$8 -> 1 | BL8: =C8+E8+G8+I8+K8+M8+O8+Q8+S8+U8+W8+Z8+AB8+AD8+AF8+AH8+AJ8+AL8+AN8+AP8+AR8+AT8+AV8+AX8+AZ8+BB8+BD8+BF8+BH8+BJ8 -> 219238536852
B9: 최대 Nego 금액 | AA9: =Z9/Z$8 -> 0 | AC9: =AB9/AB$8 -> 0 | AE9: =AD9/AD$8 -> 0 | AG9: =AF9/AF$8 -> 0 | AI9: =AH9/AH$8 -> 0 | AK9: =AJ9/AJ$8 -> 0 | AL9: 2214000000 | AM9: =AL9/AL$8 -> 0.9 | AN9: 1466100000 | AO9: =AN9/AN$8 -> 0.9 | AP9: 2700000000 | AQ9: =AP9/AP$8 -> 0.9 | AR9: 7200000000 | AS9: =AR9/AR$8 -> 0.9 | AT9: 27000000000 | AU9: =AT9/AT$8 -> 0.9 | AV9: 13500000000 | AW9: =AV9/AV$8 -> 0.9 | AX9: =AX8*0.9 -> 39600000000 | AY9: =AX9/AX$8 -> 0.9 | AZ9: =AZ8*0.9 -> 17100000000 | BA9: =AZ9/AZ$8 -> 0.9 | BB9: =BB8*0.9 -> 2250000000 | BC9: =BB9/BB$8 -> 0.9 | BD9: =BD8*0.9 -> 17100000000 | BE9: =BD9/BD$8 -> 0.9 | BF9: =BF8*0.9 -> 3600000000 | BG9: =BF9/BF$8 -> 0.9 | BH9: =BH8*0.9 -> 900000000 | BI9: =BH9/BH$8 -> 0.9 | BJ9: =BJ8*0.9 -> 18000000000 | BK9: =BJ9/BJ$8 -> 0.9 | BL9: =C9+E9+G9+I9+K9+M9+O9+Q9+S9+U9+W9+Z9+AB9+AD9+AF9+AH9+AJ9+AL9+AN9+AP9+AR9+AT9+AV9+AX9+AZ9+BB9+BD9+BF9+BH9+BJ9 -> 152630100000
B10: 프로젝트 진행률 (2026년 기준) | C10: 1 | E10: 1 | G10: 1 | I10: 1 | K10: 1 | M10: 1 | O10: 1 | Q10: 1 | S10: 1 | U10: 1 | W10: 1 | Z10: 0.3 | AB10: 1 | AD10: 1 | AF10: 1 | AH10: 0.1 | AJ10: 1 | AL10: 0.3 | AN10: 1 | AP10: 0.1 | AR10: 0.3 | AT10: 0.2 | AV10: 0.2 | AX10: 0.2 | AZ10: 0.2 | BB10: 0.5 | BD10: 0.2 | BF10: 1 | BH10: 1 | BJ10: 0.2
B11: 기계 | D11: =C11/C$8 -> 0 | F11: =E11/E$8 -> 0 | H11: =G11/G$8 -> 0 | J11: =I11/I$8 -> 0 | L11: =K11/K$8 -> 0 | N11: =M11/M$8 -> 0 | P11: =O11/O$8 -> 0 | R11: =Q11/Q$8 -> 0 | T11: =S11/S$8 -> 0 | V11: =U11/U$8 -> 0 | X11: =W11/W$8 -> 0 | Z11: =2409400000+10600000 -> 2420000000 | AB11: 1020000000 | AC11: =AB11/AB$8 -> 0.255 | AD11: 140669100 | AE11: =AD11/AD$8 -> 0.37556828 | AF11: 1789010000 | AG11: =AF11/AF$8 -> 0.55906563 | AH11: =2000000000+2700000 -> 2002700000 | AI11: =AH11/AH$8 -> 0.27112976 | AJ11: 2400000000 | AK11: =AJ11/AJ$8 -> 0.60150376 | AL11: 1520000000 | AM11: =AL11/AL$8 -> 0.61788618 | AN11: =635000000+239000000 -> 874000000 | AO11: =AN11/AN$8 -> 0.53652548 | AP11: 1900000000 | AQ11: =AP11/AP$8 -> 0.63333333 | AR11: 2300000000 | AS11: =AR11/AR$8 -> 0.2875 | AT11: =AT8*0.9 -> 27000000000 | AU11: =AT11/AT$8 -> 0.9 | AV11: =AV8*0.9 -> 13500000000 | AW11: =AV11/AV$8 -> 0.9 | AX11: =AX8*0.8 -> 35200000000 | AY11: =AX11/AX$8 -> 0.8 | AZ11: =AZ8*0.85 -> 16150000000 | BA11: =AZ11/AZ$8 -> 0.85 | BB11: =BB8*0.85 -> 2125000000 | BC11: =BB11/BB$8 -> 0.85 | BD11: =BD8*0.85 -> 16150000000 | BE11: =BD11/BD$8 -> 0.85 | BF11: =BF8*0.8 -> 3200000000 | BG11: =BF11/BF$8 -> 0.8 | BH11: =BH8*0.9 -> 900000000 | BI11: =BH11/BH$8 -> 0.9 | BJ11: =BJ8*0.85 -> 17000000000 | BK11: =BJ11/BJ$8 -> 0.85
B12: 전기 | D12: =C12/C$8 -> 0 | F12: =E12/E$8 -> 0 | H12: =G12/G$8 -> 0 | J12: =I12/I$8 -> 0 | L12: =K12/K$8 -> 0 | N12: =M12/M$8 -> 0 | P12: =O12/O$8 -> 0 | R12: =Q12/Q$8 -> 0 | T12: =S12/S$8 -> 0 | V12: =U12/U$8 -> 0 | X12: =W12/W$8 -> 0 | Z12: 270000000 | AB12: 214000000 | AC12: =AB12/AB$8 -> 0.0535 | AD12: 49995000 | AE12: =AD12/AD$8 -> 0.13348018 | AF12: 399900000 | AG12: =AF12/AF$8 -> 0.12496875 | AH12: 390600000 | AI12: =AH12/AH$8 -> 0.052880255 | AK12: =AJ12/AJ$8 -> 0 | AL12: 220000000 | AM12: =AL12/AL$8 -> 0.089430894 | AN12: 218000000 | AO12: =AN12/AN$8 -> 0.13382443 | AP12: 220000000 | AQ12: =AP12/AP$8 -> 0.073333333 | AR12: 410000000 | AS12: =AR12/AR$8 -> 0.05125 | AU12: =AT12/AT$8 -> 0 | AW12: =AV12/AV$8 -> 0 | AY12: =AX12/AX$8 -> 0 | BA12: =AZ12/AZ$8 -> 0 | BC12: =BB12/BB$8 -> 0 | BE12: =BD12/BD$8 -> 0 | BG12: =BF12/BF$8 -> 0 | BI12: =BH12/BH$8 -> 0 | BK12: =BJ12/BJ$8 -> 0
B13: 계장 | D13: =C13/C$8 -> 0 | F13: =E13/E$8 -> 0 | H13: =G13/G$8 -> 0 | J13: =I13/I$8 -> 0 | L13: =K13/K$8 -> 0 | N13: =M13/M$8 -> 0 | P13: =O13/O$8 -> 0 | R13: =Q13/Q$8 -> 0 | T13: =S13/S$8 -> 0 | V13: =U13/U$8 -> 0 | X13: =W13/W$8 -> 0 | Z13: 325000000 | AC13: =AB13/AB$8 -> 0 | AE13: =AD13/AD$8 -> 0 | AG13: =AF13/AF$8 -> 0 | AH13: 350505000 | AI13: =AH13/AH$8 -> 0.047452109 | AK13: =AJ13/AJ$8 -> 0 | AM13: =AL13/AL$8 -> 0 | AO13: =AN13/AN$8 -> 0 | AQ13: =AP13/AP$8 -> 0 | AR13: 320000000 | AS13: =AR13/AR$8 -> 0.04 | AU13: =AT13/AT$8 -> 0 | AW13: =AV13/AV$8 -> 0 | AY13: =AX13/AX$8 -> 0 | BA13: =AZ13/AZ$8 -> 0 | BC13: =BB13/BB$8 -> 0 | BE13: =BD13/BD$8 -> 0 | BG13: =BF13/BF$8 -> 0 | BI13: =BH13/BH$8 -> 0 | BK13: =BJ13/BJ$8 -> 0
B14: 배관 | D14: =C14/C$8 -> 0 | F14: =E14/E$8 -> 0 | H14: =G14/G$8 -> 0 | J14: =I14/I$8 -> 0 | L14: =K14/K$8 -> 0 | N14: =M14/M$8 -> 0 | P14: =O14/O$8 -> 0 | R14: =Q14/Q$8 -> 0 | T14: =S14/S$8 -> 0 | V14: =U14/U$8 -> 0 | X14: =W14/W$8 -> 0 | AA14: =Z14/Z$8 -> 0 | AC14: =AB14/AB$8 -> 0 | AE14: =AD14/AD$8 -> 0 | AG14: =AF14/AF$8 -> 0 | AI14: =AH14/AH$8 -> 0 | AJ14: 195000000 | AK14: =AJ14/AJ$8 -> 0.04887218 | AM14: =AL14/AL$8 -> 0 | AO14: =AN14/AN$8 -> 0 | AQ14: =AP14/AP$8 -> 0 | AS14: =AR14/AR$8 -> 0 | AU14: =AT14/AT$8 -> 0 | AW14: =AV14/AV$8 -> 0 | AY14: =AX14/AX$8 -> 0 | BA14: =AZ14/AZ$8 -> 0 | BC14: =BB14/BB$8 -> 0 | BE14: =BD14/BD$8 -> 0 | BG14: =BF14/BF$8 -> 0 | BI14: =BH14/BH$8 -> 0 | BK14: =BJ14/BJ$8 -> 0
B15: 회전기기 | D15: =C15/C$8 -> 0 | F15: =E15/E$8 -> 0 | H15: =G15/G$8 -> 0 | J15: =I15/I$8 -> 0 | L15: =K15/K$8 -> 0 | N15: =M15/M$8 -> 0 | P15: =O15/O$8 -> 0 | R15: =Q15/Q$8 -> 0 | T15: =S15/S$8 -> 0 | V15: =U15/U$8 -> 0 | X15: =W15/W$8 -> 0 | Z15: 330000000 | AA15: =Z15/Z$8 -> 0.014132762 | AB15: 170000000 | AC15: =AB15/AB$8 -> 0.0425 | AE15: =AD15/AD$8 -> 0 | AF15: 146300000 | AG15: =AF15/AF$8 -> 0.04571875 | AH15: 234000000 | AI15: =AH15/AH$8 -> 0.031679415 | AJ15: 320000000 | AK15: =AJ15/AJ$8 -> 0.080200501 | AM15: =AL15/AL$8 -> 0 | AN15: 94000000 | AO15: =AN15/AN$8 -> 0.057704113 | AQ15: =AP15/AP$8 -> 0 | AR15: 150000000 | AS15: =AR15/AR$8 -> 0.01875 | AU15: =AT15/AT$8 -> 0 | AW15: =AV15/AV$8 -> 0 | AY15: =AX15/AX$8 -> 0 | BA15: =AZ15/AZ$8 -> 0 | BC15: =BB15/BB$8 -> 0 | BE15: =BD15/BD$8 -> 0 | BG15: =BF15/BF$8 -> 0 | BI15: =BH15/BH$8 -> 0 | BK15: =BJ15/BJ$8 -> 0
B16: 열교환기 | D16: =C16/C$8 -> 0 | F16: =E16/E$8 -> 0 | H16: =G16/G$8 -> 0 | J16: =I16/I$8 -> 0 | L16: =K16/K$8 -> 0 | N16: =M16/M$8 -> 0 | P16: =O16/O$8 -> 0 | R16: =Q16/Q$8 -> 0 | T16: =S16/S$8 -> 0 | V16: =U16/U$8 -> 0 | X16: =W16/W$8 -> 0 | AA16: =Z16/Z$8 -> 0 | AB16: 649000000 | AC16: =AB16/AB$8 -> 0.16225 | AE16: =AD16/AD$8 -> 0 | AG16: =AF16/AF$8 -> 0 | AI16: =AH16/AH$8 -> 0 | AJ16: 240000000 | AK16: =AJ16/AJ$8 -> 0.060150376 | AM16: =AL16/AL$8 -> 0 | AO16: =AN16/AN$8 -> 0 | AQ16: =AP16/AP$8 -> 0 | AS16: =AR16/AR$8 -> 0 | AU16: =AT16/AT$8 -> 0 | AW16: =AV16/AV$8 -> 0 | AY16: =AX16/AX$8 -> 0 | BA16: =AZ16/AZ$8 -> 0 | BC16: =BB16/BB$8 -> 0 | BE16: =BD16/BD$8 -> 0 | BG16: =BF16/BF$8 -> 0 | BI16: =BH16/BH$8 -> 0 | BK16: =BJ16/BJ$8 -> 0
B17: 촉매 | D17: =C17/C$8 -> 0 | F17: =E17/E$8 -> 0 | H17: =G17/G$8 -> 0 | J17: =I17/I$8 -> 0 | L17: =K17/K$8 -> 0 | N17: =M17/M$8 -> 0 | P17: =O17/O$8 -> 0 | R17: =Q17/Q$8 -> 0 | T17: =S17/S$8 -> 0 | V17: =U17/U$8 -> 0 | X17: =W17/W$8 -> 0 | Z17: 15300000000 | AA17: =Z17/Z$8 -> 0.65524625 | AC17: =AB17/AB$8 -> 0 | AE17: =AD17/AD$8 -> 0 | AF17: 67890000 | AG17: =AF17/AF$8 -> 0.021215625 | AH17: =1991000*1500 -> 2986500000 | AI17: =AH17/AH$8 -> 0.40431869 | AK17: =AJ17/AJ$8 -> 0 | AM17: =AL17/AL$8 -> 0 | AO17: =AN17/AN$8 -> 0 | AQ17: =AP17/AP$8 -> 0 | AR17: 2550000000 | AS17: =AR17/AR$8 -> 0.31875 | AU17: =AT17/AT$8 -> 0 | AW17: =AV17/AV$8 -> 0 | AY17: =AX17/AX$8 -> 0 | BA17: =AZ17/AZ$8 -> 0 | BC17: =BB17/BB$8 -> 0 | BE17: =BD17/BD$8 -> 0 | BG17: =BF17/BF$8 -> 0 | BI17: =BH17/BH$8 -> 0 | BK17: =BJ17/BJ$8 -> 0
B18: 분석기 | D18: =C18/C$8 -> 0 | F18: =E18/E$8 -> 0 | H18: =G18/G$8 -> 0 | J18: =I18/I$8 -> 0 | L18: =K18/K$8 -> 0 | N18: =M18/M$8 -> 0 | P18: =O18/O$8 -> 0 | R18: =Q18/Q$8 -> 0 | T18: =S18/S$8 -> 0 | V18: =U18/U$8 -> 0 | X18: =W18/W$8 -> 0 | Z18: 1780000000 | AC18: =AB18/AB$8 -> 0 | AE18: =AD18/AD$8 -> 0 | AF18: 106700000 | AG18: =AF18/AF$8 -> 0.03334375 | AH18: 423000000 | AI18: =AH18/AH$8 -> 0.057266635 | AK18: =AJ18/AJ$8 -> 0 | AM18: =AL18/AL$8 -> 0 | AO18: =AN18/AN$8 -> 0 | AQ18: =AP18/AP$8 -> 0 | AR18: 360000000 | AS18: =AR18/AR$8 -> 0.045 | AU18: =AT18/AT$8 -> 0 | AW18: =AV18/AV$8 -> 0 | AY18: =AX18/AX$8 -> 0 | BA18: =AZ18/AZ$8 -> 0 | BC18: =BB18/BB$8 -> 0 | BE18: =BD18/BD$8 -> 0 | BG18: =BF18/BF$8 -> 0 | BI18: =BH18/BH$8 -> 0 | BK18: =BJ18/BJ$8 -> 0
B19: 버너 | D19: =C19/C$8 -> 0 | F19: =E19/E$8 -> 0 | H19: =G19/G$8 -> 0 | J19: =I19/I$8 -> 0 | L19: =K19/K$8 -> 0 | N19: =M19/M$8 -> 0 | P19: =O19/O$8 -> 0 | R19: =Q19/Q$8 -> 0 | T19: =S19/S$8 -> 0 | V19: =U19/U$8 -> 0 | X19: =W19/W$8 -> 0 | AA19: =Z19/Z$8 -> 0 | AC19: =AB19/AB$8 -> 0 | AE19: =AD19/AD$8 -> 0 | AF19: 23750000 | AG19: =AF19/AF$8 -> 0.007421875 | AI19: =AH19/AH$8 -> 0 | AK19: =AJ19/AJ$8 -> 0 | AM19: =AL19/AL$8 -> 0 | AO19: =AN19/AN$8 -> 0 | AQ19: =AP19/AP$8 -> 0 | AS19: =AR19/AR$8 -> 0 | AU19: =AT19/AT$8 -> 0 | AW19: =AV19/AV$8 -> 0 | AY19: =AX19/AX$8 -> 0 | BA19: =AZ19/AZ$8 -> 0 | BC19: =BB19/BB$8 -> 0 | BE19: =BD19/BD$8 -> 0 | BG19: =BF19/BF$8 -> 0 | BI19: =BH19/BH$8 -> 0 | BK19: =BJ19/BJ$8 -> 0
B20: Filter | D20: =C20/C$8 -> 0 | F20: =E20/E$8 -> 0 | H20: =G20/G$8 -> 0 | J20: =I20/I$8 -> 0 | L20: =K20/K$8 -> 0 | N20: =M20/M$8 -> 0 | P20: =O20/O$8 -> 0 | R20: =Q20/Q$8 -> 0 | T20: =S20/S$8 -> 0 | V20: =U20/U$8 -> 0 | X20: =W20/W$8 -> 0 | AA20: =Z20/Z$8 -> 0 | AB20: 550000000 | AC20: =AB20/AB$8 -> 0.1375 | AD20: 52800000 | AE20: =AD20/AD$8 -> 0.14096916 | AG20: =AF20/AF$8 -> 0 | AI20: =AH20/AH$8 -> 0 | AK20: =AJ20/AJ$8 -> 0 | AM20: =AL20/AL$8 -> 0 | AO20: =AN20/AN$8 -> 0 | AQ20: =AP20/AP$8 -> 0 | AS20: =AR20/AR$8 -> 0 | AU20: =AT20/AT$8 -> 0 | AW20: =AV20/AV$8 -> 0 | AY20: =AX20/AX$8 -> 0 | BA20: =AZ20/AZ$8 -> 0 | BC20: =BB20/BB$8 -> 0 | BE20: =BD20/BD$8 -> 0 | BG20: =BF20/BF$8 -> 0 | BI20: =BH20/BH$8 -> 0 | BK20: =BJ20/BJ$8 -> 0
B21: 활성탄 | D21: =C21/C$8 -> 0 | F21: =E21/E$8 -> 0 | H21: =G21/G$8 -> 0 | J21: =I21/I$8 -> 0 | L21: =K21/K$8 -> 0 | N21: =M21/M$8 -> 0 | P21: =O21/O$8 -> 0 | R21: =Q21/Q$8 -> 0 | T21: =S21/S$8 -> 0 | V21: =U21/U$8 -> 0 | X21: =W21/W$8 -> 0 | AA21: =Z21/Z$8 -> 0 | AB21: 250000000 | AC21: =AB21/AB$8 -> 0.0625 | AE21: =AD21/AD$8 -> 0 | AG21: =AF21/AF$8 -> 0 | AI21: =AH21/AH$8 -> 0 | AK21: =AJ21/AJ$8 -> 0 | AM21: =AL21/AL$8 -> 0 | AN21: 19200000 | AO21: =AN21/AN$8 -> 0.011786372 | AQ21: =AP21/AP$8 -> 0 | AS21: =AR21/AR$8 -> 0 | AU21: =AT21/AT$8 -> 0 | AW21: =AV21/AV$8 -> 0 | AY21: =AX21/AX$8 -> 0 | BA21: =AZ21/AZ$8 -> 0 | BC21: =BB21/BB$8 -> 0 | BE21: =BD21/BD$8 -> 0 | BG21: =BF21/BF$8 -> 0 | BI21: =BH21/BH$8 -> 0 | BK21: =BJ21/BJ$8 -> 0
B22: 방음룸 | D22: =C22/C$8 -> 0 | F22: =E22/E$8 -> 0 | H22: =G22/G$8 -> 0 | J22: =I22/I$8 -> 0 | L22: =K22/K$8 -> 0 | N22: =M22/M$8 -> 0 | P22: =O22/O$8 -> 0 | R22: =Q22/Q$8 -> 0 | T22: =S22/S$8 -> 0 | V22: =U22/U$8 -> 0 | X22: =W22/W$8 -> 0 | AA22: =Z22/Z$8 -> 0 | AB22: 120000000 | AC22: =AB22/AB$8 -> 0.03 | AE22: =AD22/AD$8 -> 0 | AG22: =AF22/AF$8 -> 0 | AI22: =AH22/AH$8 -> 0 | AK22: =AJ22/AJ$8 -> 0 | AM22: =AL22/AL$8 -> 0 | AO22: =AN22/AN$8 -> 0 | AQ22: =AP22/AP$8 -> 0 | AS22: =AR22/AR$8 -> 0 | AU22: =AT22/AT$8 -> 0 | AW22: =AV22/AV$8 -> 0 | AY22: =AX22/AX$8 -> 0 | BA22: =AZ22/AZ$8 -> 0 | BC22: =BB22/BB$8 -> 0 | BE22: =BD22/BD$8 -> 0 | BG22: =BF22/BF$8 -> 0 | BI22: =BH22/BH$8 -> 0 | BK22: =BJ22/BJ$8 -> 0
B23: 안전관리비 | D23: =C23/C$8 -> 0 | F23: =E23/E$8 -> 0 | H23: =G23/G$8 -> 0 | J23: =I23/I$8 -> 0 | L23: =K23/K$8 -> 0 | N23: =M23/M$8 -> 0 | P23: =O23/O$8 -> 0 | R23: =Q23/Q$8 -> 0 | T23: =S23/S$8 -> 0 | V23: =U23/U$8 -> 0 | X23: =W23/W$8 -> 0 | AA23: =Z23/Z$8 -> 0 | AB23: 30000000 | AC23: =AB23/AB$8 -> 0.0075 | AE23: =AD23/AD$8 -> 0 | AF23: 25000000 | AG23: =AF23/AF$8 -> 0.0078125 | AI23: =AH23/AH$8 -> 0 | AJ23: 40000000 | AK23: =AJ23/AJ$8 -> 0.010025063 | AL23: 45000000 | AM23: =AL23/AL$8 -> 0.018292683 | AO23: =AN23/AN$8 -> 0 | AP23: 55000000 | AQ23: =AP23/AP$8 -> 0.018333333 | AS23: =AR23/AR$8 -> 0 | AU23: =AT23/AT$8 -> 0 | AW23: =AV23/AV$8 -> 0 | AY23: =AX23/AX$8 -> 0 | BA23: =AZ23/AZ$8 -> 0 | BC23: =BB23/BB$8 -> 0 | BE23: =BD23/BD$8 -> 0 | BG23: =BF23/BF$8 -> 0 | BI23: =BH23/BH$8 -> 0 | BK23: =BJ23/BJ$8 -> 0
B24: 외주용역 | D24: =C24/C$8 -> 0 | F24: =E24/E$8 -> 0 | H24: =G24/G$8 -> 0 | J24: =I24/I$8 -> 0 | L24: =K24/K$8 -> 0 | N24: =M24/M$8 -> 0 | P24: =O24/O$8 -> 0 | R24: =Q24/Q$8 -> 0 | T24: =S24/S$8 -> 0 | V24: =U24/U$8 -> 0 | X24: =W24/W$8 -> 0 | Z24: 390000000 | AA24: =Z24/Z$8 -> 0.016702355 | AC24: =AB24/AB$8 -> 0 | AE24: =AD24/AD$8 -> 0 | AF24: 15000000 | AG24: =AF24/AF$8 -> 0.0046875 | AH24: 289620000 | AI24: =AH24/AH$8 -> 0.039209368 | AJ24: 125000000 | AK24: =AJ24/AJ$8 -> 0.031328321 | AL24: 71000000 | AM24: =AL24/AL$8 -> 0.028861789 | AN24: 20000000 | AO24: =AN24/AN$8 -> 0.012277471 | AP24: 80000000 | AQ24: =AP24/AP$8 -> 0.026666667 | AR24: 280000000 | AS24: =AR24/AR$8 -> 0.035 | AU24: =AT24/AT$8 -> 0 | AW24: =AV24/AV$8 -> 0 | AY24: =AX24/AX$8 -> 0 | BA24: =AZ24/AZ$8 -> 0 | BC24: =BB24/BB$8 -> 0 | BE24: =BD24/BD$8 -> 0 | BG24: =BF24/BF$8 -> 0 | BI24: =BH24/BH$8 -> 0 | BK24: =BJ24/BJ$8 -> 0
B25: 기타 | D25: =C25/C$8 -> 0 | F25: =E25/E$8 -> 0 | H25: =G25/G$8 -> 0 | J25: =I25/I$8 -> 0 | L25: =K25/K$8 -> 0 | N25: =M25/M$8 -> 0 | P25: =O25/O$8 -> 0 | R25: =Q25/Q$8 -> 0 | T25: =S25/S$8 -> 0 | V25: =U25/U$8 -> 0 | X25: =W25/W$8 -> 0 | Z25: 821000000 | AA25: =Z25/Z$8 -> 0.0351606 | AB25: =90000000+15000000 -> 105000000 | AC25: =AB25/AB$8 -> 0.02625 | AD25: =19800000+23565000+9900000+7491000 -> 60756000 | AE25: =AD25/AD$8 -> 0.16221065 | AF25: =45000000 -> 45000000 | AG25: =AF25/AF$8 -> 0.0140625 | AH25: 163200000 | AI25: =AH25/AH$8 -> 0.022094361 | AJ25: =45000000+40000000+40000000+60000000+90000000 -> 275000000 | AK25: =AJ25/AJ$8 -> 0.068922306 | AL25: =20000000+6500000 -> 26500000 | AM25: =AL25/AL$8 -> 0.010772358 | AN25: =98000000 -> 98000000 | AO25: =AN25/AN$8 -> 0.060159607 | AQ25: =AP25/AP$8 -> 0 | AR25: 180000000 | AS25: =AR25/AR$8 -> 0.0225 | AU25: =AT25/AT$8 -> 0 | AW25: =AV25/AV$8 -> 0 | AY25: =AX25/AX$8 -> 0 | BA25: =AZ25/AZ$8 -> 0 | BC25: =BB25/BB$8 -> 0 | BE25: =BD25/BD$8 -> 0 | BG25: =BF25/BF$8 -> 0 | BI25: =BH25/BH$8 -> 0 | BK25: =BJ25/BJ$8 -> 0
B26: 이자비용 | D26: =C26/C$8 -> 0 | F26: =E26/E$8 -> 0 | H26: =G26/G$8 -> 0 | J26: =I26/I$8 -> 0 | L26: =K26/K$8 -> 0 | N26: =M26/M$8 -> 0 | P26: =O26/O$8 -> 0 | R26: =Q26/Q$8 -> 0 | T26: =S26/S$8 -> 0 | V26: =U26/U$8 -> 0 | X26: =W26/W$8 -> 0 | AA26: =Z26/Z$8 -> 0 | AC26: =AB26/AB$8 -> 0 | AE26: =AD26/AD$8 -> 0 | AG26: =AF26/AF$8 -> 0 | AI26: =AH26/AH$8 -> 0 | AK26: =AJ26/AJ$8 -> 0 | AM26: =AL26/AL$8 -> 0 | AO26: =AN26/AN$8 -> 0 | AQ26: =AP26/AP$8 -> 0 | AS26: =AR26/AR$8 -> 0 | AU26: =AT26/AT$8 -> 0 | AW26: =AV26/AV$8 -> 0 | AY26: =AX26/AX$8 -> 0 | BA26: =AZ26/AZ$8 -> 0 | BC26: =BB26/BB$8 -> 0 | BE26: =BD26/BD$8 -> 0 | BG26: =BF26/BF$8 -> 0 | BI26: =BH26/BH$8 -> 0 | BK26: =BJ26/BJ$8 -> 0
B27: 제조직접원가 | C27: =C8*D27 -> 2.4495666e+09 | D27: =D29-D28 -> 0.89361311 | E27: =E8*F27 -> 1.5561499e+09 | F27: =F29-F28 -> 0.86776087 | G27: =G8*H27 -> 1.061544e+09 | H27: =H29-H28 -> 0.8613034 | I27: =I8*J27 -> 7.4864544e+08 | J27: =J29-J28 -> 0.957 | K27: =K8*L27 -> 3.4489968e+08 | L27: =L29-L28 -> 0.84661197 | M27: =M8*N27 -> 1.4343104e+08 | N27: =N29-N28 -> 0.8870441 | O27: =O8*P27 -> 118000000 | P27: =P29-P28 -> 1 | Q27: =Q8*R27 -> 32100000 | R27: =R29-R28 -> 0.78484108 | S27: =S8*T27 -> 25867420 | T27: =T29-T28 -> 0.80835687 | U27: =U8*V27 -> 24878346 | V27: =V29-V28 -> 0.81523142 | W27: =W8*X27 -> 7339205.9 | X27: =X29-X28 -> 0.84068796 | Z27: =SUM(Z11:Z26) -> 21636000000 | AA27: =Z27/Z$8 -> 0.92659529 | AB27: =SUM(AB11:AB26) -> 3108000000 | AC27: =AB27/AB$8 -> 0.777 | AD27: =SUM(AD11:AD26) -> 304220100 | AE27: =AD27/AD$8 -> 0.81222827 | AF27: =SUM(AF11:AF26) -> 2618550000 | AG27: =AF27/AF$8 -> 0.81829688 | AH27: =SUM(AH11:AH26) -> 6840125000 | AI27: =AH27/AH$8 -> 0.9260306 | AJ27: =SUM(AJ11:AJ26) -> 3595000000 | AK27: =AJ27/AJ$8 -> 0.90100251 | AL27: =SUM(AL11:AL26) -> 1882500000 | AM27: =AL27/AL$8 -> 0.7652439 | AN27: =SUM(AN11:AN26) -> 1323200000 | AO27: =AN27/AN$8 -> 0.81227747 | AP27: =SUM(AP11:AP26) -> 2255000000 | AQ27: =AP27/AP$8 -> 0.75166667 | AR27: =SUM(AR11:AR26) -> 6550000000 | AS27: =AR27/AR$8 -> 0.81875 | AT27: =SUM(AT11:AT26) -> 27000000000 | AU27: =AT27/AT$8 -> 0.9 | AV27: =SUM(AV11:AV26) -> 13500000000 | AW27: =AV27/AV$8 -> 0.9 | AX27: =SUM(AX11:AX26) -> 35200000000 | AY27: =AX27/AX$8 -> 0.8 | AZ27: =SUM(AZ11:AZ26) -> 16150000000 | BA27: =AZ27/AZ$8 -> 0.85 | BB27: =SUM(BB11:BB26) -> 2125000000 | BC27: =BB27/BB$8 -> 0.85 | BD27: =SUM(BD11:BD26) -> 16150000000 | BE27: =BD27/BD$8 -> 0.85 | BF27: =SUM(BF11:BF26) -> 3200000000 | BG27: =BF27/BF$8 -> 0.8 | BH27: =SUM(BH11:BH26) -> 900000000 | BI27: =BH27/BH$8 -> 0.9 | BJ27: =SUM(BJ11:BJ26) -> 17000000000 | BK27: =BJ27/BJ$8 -> 0.85 | BL27: =C27+E27+G27+I27+K27+M27+O27+Q27+S27+U27+W27+Z27+AB27+AD27+AF27+AH27+AJ27+AL27+AN27+AP27+AR27+AT27+AV27+AX27+AZ27+BB27+BD27+BF27+BH27+BJ27 -> 1.8785002e+11
B28: 제조간접원가 | C28: =C8*D28 -> 1.1787132e+08 | D28: 0.043 | E28: =E8*F28 -> 77111618 | F28: 0.043 | G28: =G8*H28 -> 2464971.2 | H28: 0.002 | I28: =I8*J28 -> 33638196 | J28: 0.043 | K28: =K8*L28 -> 17517690 | L28: 0.043 | M28: =M8*N28 -> 12127162 | N28: 0.075 | O28: =O8*P28 -> 0 | P28: 0 | Q28: =Q8*R28 -> 1758700 | R28: 0.043 | S28: =S8*T28 -> 1376000 | T28: 0.043 | U28: =U8*V28 -> 1312227.2 | V28: 0.043 | W28: =W8*X28 -> 820620 | X28: 0.094 | Z28: =Z8*AA28 -> 1284250000 | AA28: 0.055 | AB28: =AB8*AC28 -> 220000000 | AC28: 0.055 | AD28: =AD8*AE28 -> 20600250 | AE28: 0.055 | AF28: =AF8*AG28 -> 176000000 | AG28: 0.055 | AH28: =AH8*AI28 -> 406257500 | AI28: 0.055 | AJ28: =AJ8*AK28 -> 219450000 | AK28: 0.055 | AL28: =AL8*AM28 -> 135300000 | AM28: 0.055 | AN28: =AN8*AO28 -> 89595000 | AO28: 0.055 | AP28: =AP8*AQ28 -> 165000000 | AQ28: 0.055 | AR28: =AR8*AS28 -> 440000000 | AS28: 0.055 | AT28: =AT8*AU28 -> 1650000000 | AU28: 0.055 | AV28: =AV8*AW28 -> 825000000 | AW28: 0.055 | AX28: =AX8*AY28 -> 2420000000 | AY28: 0.055 | AZ28: =AZ8*BA28 -> 1045000000 | BA28: 0.055 | BB28: =BB8*BC28 -> 137500000 | BC28: 0.055 | BD28: =BD8*BE28 -> 1045000000 | BE28: 0.055 | BF28: =BF8*BG28 -> 220000000 | BG28: 0.055 | BH28: =BH8*BI28 -> 55000000 | BI28: 0.055 | BJ28: =BJ8*BK28 -> 1100000000 | BK28: 0.055 | BL28: =C28+E28+G28+I28+K28+M28+O28+Q28+S28+U28+W28+Z28+AB28+AD28+AF28+AH28+AJ28+AL28+AN28+AP28+AR28+AT28+AV28+AX28+AZ28+BB28+BD28+BF28+BH28+BJ28 -> 1.1919951e+10
B29: 제조원가 | C29: =C8*D29 -> 2.5674379e+09 | D29: 0.93661311 | E29: =E8*F29 -> 1.6332615e+09 | F29: 0.91076087 | G29: =G8*H29 -> 1.064009e+09 | H29: 0.8633034 | I29: =I8*J29 -> 782283637 | J29: 1 | K29: =K8*L29 -> 3.6241737e+08 | L29: 0.88961197 | M29: =M8*N29 -> 1.555582e+08 | N29: 0.9620441 | O29: =O8*P29 -> 118000000 | P29: 1 | Q29: =Q8*R29 -> 33858700 | R29: 0.82784108 | S29: =S8*T29 -> 27243420 | T29: 0.85135688 | U29: =U8*V29 -> 26190573 | V29: 0.85823142 | W29: =W8*X29 -> 8159825.9 | X29: 0.93468796 | Z29: =Z27+Z28 -> 22920250000 | AA29: =Z29/Z$8 -> 0.98159529 | AB29: =AB27+AB28 -> 3328000000 | AC29: =AB29/AB$8 -> 0.832 | AD29: =AD27+AD28 -> 324820350 | AE29: =AD29/AD$8 -> 0.86722827 | AF29: =AF27+AF28 -> 2794550000 | AG29: =AF29/AF$8 -> 0.87329687 | AH29: =AH27+AH28 -> 7246382500 | AI29: =AH29/AH$8 -> 0.9810306 | AJ29: =AJ27+AJ28 -> 3814450000 | AK29: =AJ29/AJ$8 -> 0.95600251 | AL29: =AL27+AL28 -> 2017800000 | AM29: =AL29/AL$8 -> 0.8202439 | AN29: =AN27+AN28 -> 1412795000 | AO29: =AN29/AN$8 -> 0.86727747 | AP29: =AP27+AP28 -> 2420000000 | AQ29: =AP29/AP$8 -> 0.80666667 | AR29: =AR27+AR28 -> 6990000000 | AS29: =AR29/AR$8 -> 0.87375 | AT29: =AT27+AT28 -> 28650000000 | AU29: =AT29/AT$8 -> 0.955 | AV29: =AV27+AV28 -> 14325000000 | AW29: =AV29/AV$8 -> 0.955 | AX29: =AX27+AX28 -> 37620000000 | AY29: =AX29/AX$8 -> 0.855 | AZ29: =AZ27+AZ28 -> 17195000000 | BA29: =AZ29/AZ$8 -> 0.905 | BB29: =BB27+BB28 -> 2262500000 | BC29: =BB29/BB$8 -> 0.905 | BD29: =BD27+BD28 -> 17195000000 | BE29: =BD29/BD$8 -> 0.905 | BF29: =BF27+BF28 -> 3420000000 | BG29: =BF29/BF$8 -> 0.855 | BH29: =BH27+BH28 -> 955000000 | BI29: =BH29/BH$8 -> 0.955 | BJ29: =BJ27+BJ28 -> 18100000000 | BK29: =BJ29/BJ$8 -> 0.905 | BL29: =C29+E29+G29+I29+K29+M29+O29+Q29+S29+U29+W29+Z29+AB29+AD29+AF29+AH29+AJ29+AL29+AN29+AP29+AR29+AT29+AV29+AX29+AZ29+BB29+BD29+BF29+BH29+BJ29 -> 1.9976997e+11
B30: 판관비 | C30: =C8*D30 -> 3.3716681e+08 | D30: 0.123 | E30: =E8*F30 -> 2.2057509e+08 | F30: 0.123 | G30: =G8*H30 -> 1.5159573e+08 | H30: 0.123 | I30: =I8*J30 -> 96220887 | J30: 0.123 | K30: =K8*L30 -> 50108742 | L30: 0.123 | M30: =M8*N30 -> 19888546 | N30: 0.123 | O30: =O8*P30 -> 14514000 | P30: 0.123 | Q30: =Q8*R30 -> 5030700 | R30: 0.123 | S30: =S8*T30 -> 3936000 | T30: 0.123 | U30: =U8*V30 -> 3753580.2 | V30: 0.123 | W30: =W8*X30 -> 1073790 | X30: 0.123 | Z30: =Z8*AA30 -> 2872050000 | AA30: 0.123 | AB30: =AB8*AC30 -> 492000000 | AC30: 0.123 | AD30: =AD8*AE30 -> 46069650 | AE30: 0.123 | AF30: =AF8*AG30 -> 393600000 | AG30: 0.123 | AH30: =AH8*AI30 -> 908539500 | AI30: 0.123 | AJ30: =AJ8*AK30 -> 490770000 | AK30: 0.123 | AL30: =AL8*AM30 -> 302580000 | AM30: 0.123 | AN30: =AN8*AO30 -> 200367000 | AO30: 0.123 | AP30: =AP8*AQ30 -> 369000000 | AQ30: 0.123 | AR30: =AR8*AS30 -> 984000000 | AS30: 0.123 | AT30: =AT8*AU30 -> 3690000000 | AU30: 0.123 | AV30: =AV8*AW30 -> 1845000000 | AW30: 0.123 | AX30: =AX8*AY30 -> 5412000000 | AY30: 0.123 | AZ30: =AZ8*BA30 -> 2337000000 | BA30: 0.123 | BB30: =BB8*BC30 -> 307500000 | BC30: 0.123 | BD30: =BD8*BE30 -> 2337000000 | BE30: 0.123 | BF30: =BF8*BG30 -> 492000000 | BG30: 0.123 | BH30: =BH8*BI30 -> 123000000 | BI30: 0.123 | BJ30: =BJ8*BK30 -> 2460000000 | BK30: 0.123 | BL30: =C30+E30+G30+I30+K30+M30+O30+Q30+S30+U30+W30+Z30+AB30+AD30+AF30+AH30+AJ30+AL30+AN30+AP30+AR30+AT30+AV30+AX30+AZ30+BB30+BD30+BF30+BH30+BJ30 -> 2.696634e+10
B31: 영업이익 | C31: =C8-C29-C30 -> -1.6341109e+08 | D31: =C31/C$8 -> -0.059613115 | E31: =E8-E29-E30 -> -60543146 | F31: =E31/E$8 -> -0.03376087 | G31: =G8-G29-G30 -> 16880864 | H31: =G31/G$8 -> 0.013696601 | I31: =I8-I29-I30 -> -96220887 | J31: =I31/I$8 -> -0.123 | K31: =K8-K29-K30 -> -5137965.4 | L31: =K31/K$8 -> -0.012611966 | M31: =M8-M29-M30 -> -13751248 | N31: =M31/M$8 -> -0.085044096 | O31: =O8-O29-O30 -> -14514000 | P31: =O31/O$8 -> -0.123 | Q31: =Q8-Q29-Q30 -> 2010600 | R31: =Q31/Q$8 -> 0.049158924 | S31: =S8-S29-S30 -> 820580 | T31: =S31/S$8 -> 0.025643125 | U31: =U8-U29-U30 -> 572758.99 | V31: =U31/U$8 -> 0.018768576 | W31: =W8-W29-W30 -> -503615.88 | X31: =W31/W$8 -> -0.057687959 | Z31: =Z8-Z29-Z30 -> -2442300000 | AA31: =Z31/Z$8 -> -0.10459529 | AB31: =AB8-AB29-AB30 -> 180000000 | AC31: =AB31/AB$8 -> 0.045 | AD31: =AD8-AD29-AD30 -> 3660000 | AE31: =AD31/AD$8 -> 0.0097717261 | AF31: =AF8-AF29-AF30 -> 11850000 | AG31: =AF31/AF$8 -> 0.003703125 | AH31: =AH8-AH29-AH30 -> -768422000 | AI31: =AH31/AH$8 -> -0.1040306 | AJ31: =AJ8-AJ29-AJ30 -> -315220000 | AK31: =AJ31/AJ$8 -> -0.079002506 | AL31: =AL8-AL29-AL30 -> 139620000 | AM31: =AL31/AL$8 -> 0.056756098 | AN31: =AN8-AN29-AN30 -> 15838000 | AO31: =AN31/AN$8 -> 0.0097225292 | AP31: =AP8-AP29-AP30 -> 211000000 | AQ31: =AP31/AP$8 -> 0.070333333 | AR31: =AR8-AR29-AR30 -> 26000000 | AS31: =AR31/AR$8 -> 0.00325 | AT31: =AT8-AT29-AT30 -> -2340000000 | AU31: =AT31/AT$8 -> -0.078 | AV31: =AV8-AV29-AV30 -> -1170000000 | AW31: =AV31/AV$8 -> -0.078 | AX31: =AX8-AX29-AX30 -> 968000000 | AY31: =AX31/AX$8 -> 0.022 | AZ31: =AZ8-AZ29-AZ30 -> -532000000 | BA31: =AZ31/AZ$8 -> -0.028 | BB31: =BB8-BB29-BB30 -> -70000000 | BC31: =BB31/BB$8 -> -0.028 | BD31: =BD8-BD29-BD30 -> -532000000 | BE31: =BD31/BD$8 -> -0.028 | BF31: =BF8-BF29-BF30 -> 88000000 | BG31: =BF31/BF$8 -> 0.022 | BH31: =BH8-BH29-BH30 -> -78000000 | BI31: =BH31/BH$8 -> -0.078 | BJ31: =BJ8-BJ29-BJ30 -> -560000000 | BK31: =BJ31/BJ$8 -> -0.028 | BL31: =C31+E31+G31+I31+K31+M31+O31+Q31+S31+U31+W31+Z31+AB31+AD31+AF31+AH31+AJ31+AL31+AN31+AP31+AR31+AT31+AV31+AX31+AZ31+BB31+BD31+BF31+BH31+BJ31 -> -7.4977711e+09
Z32: =Z30+Z31+Z28 -> 1714000000 | AA32: =Z32/Z8 -> 0.073404711
B33: 2. '26년 프로젝트별 손익
B34: '26년 매출반영 | C34: =C8*C10 -> 2741193600 | D34: =C34/C$34 -> 1 | E34: =E8*E10 -> 1793293440 | F34: =E34/E$34 -> 1 | G34: =G8*G10 -> 1232485613 | H34: =G34/G$34 -> 1 | I34: =I8*I10 -> 782283637 | J34: =I34/I$34 -> 1 | K34: =K8*K10 -> 407388150 | L34: =K34/K$34 -> 1 | M34: =M8*M10 -> 161695500 | N34: =M34/M$34 -> 1 | O34: =O8*O10 -> 118000000 | P34: =O34/O$34 -> 1 | Q34: =Q8*Q10 -> 40900000 | R34: =Q34/Q$34 -> 1 | S34: =S8*S10 -> 32000000 | T34: =S34/S$34 -> 1 | U34: =U8*U10 -> 30516912 | V34: =U34/U$34 -> 1 | W34: =W8*W10 -> 8730000 | X34: =W34/W$34 -> 1 | Z34: =Z8*Z10 -> 7005000000 | AA34: =Z34/Z$34 -> 1 | AB34: =AB8*AB10 -> 4000000000 | AC34: =AB34/AB$34 -> 1 | AD34: =AD8*AD10 -> 374550000 | AE34: =AD34/AD$34 -> 1 | AF34: =AF8*AF10 -> 3200000000 | AG34: =AF34/AF$34 -> 1 | AH34: =AH8*AH10 -> 738650000 | AI34: =AH34/AH$34 -> 1 | AJ34: =AJ8*AJ10 -> 3990000000 | AK34: =AJ34/AJ$34 -> 1 | AL34: =AL8*AL10 -> 738000000 | AM34: =AL34/AL$34 -> 1 | AN34: =AN8*AN10 -> 1629000000 | AO34: =AN34/AN$34 -> 1 | AP34: =AP8*AP10 -> 300000000 | AQ34: =AP34/AP$34 -> 1 | AR34: =AR8*AR10 -> 2400000000 | AS34: =AR34/AR$34 -> 1 | AT34: =AT8*AT10 -> 6000000000 | AU34: =AT34/AT$34 -> 1 | AV34: =AV8*AV10 -> 3000000000 | AW34: =AV34/AV$34 -> 1 | AX34: =AX8*AX10 -> 8800000000 | AY34: =AX34/AX$34 -> 1 | AZ34: =AZ8*AZ10 -> 3800000000 | BA34: =AZ34/AZ$34 -> 1 | BB34: =BB8*BB10 -> 1250000000 | BC34: =BB34/BB$34 -> 1 | BD34: =BD8*BD10 -> 3800000000 | BE34: =BD34/BD$34 -> 1 | BF34: =BF8*BF10 -> 4000000000 | BG34: =BF34/BF$34 -> 1 | BH34: =BH8*BH10 -> 1000000000 | BI34: =BH34/BH$34 -> 1 | BJ34: =BJ8*BJ10 -> 4000000000 | BK34: =BJ34/BJ$34 -> 1 | BL34: =C34+E34+G34+I34+K34+M34+O34+Q34+S34+U34+W34+Z34+AB34+AD34+AF34+AH34+AJ34+AL34+AN34+AP34+AR34+AT34+AV34+AX34+AZ34+BB34+BD34+BF34+BH34+BJ34 -> 67373686852 | BM34: =BL34/BL$34 -> 1
B35: '26년 제조간접원가 | C35: =C28*C10 -> 1.1787132e+08 | D35: =C35/C$34 -> 0.043 | E35: =E28*E10 -> 77111618 | F35: =E35/E$34 -> 0.043 | G35: =G28*G10 -> 2464971.2 | H35: =G35/G$34 -> 0.002 | I35: =I28*I10 -> 33638196 | J35: =I35/I$34 -> 0.043 | K35: =K28*K10 -> 17517690 | L35: =K35/K$34 -> 0.043 | M35: =M28*M10 -> 12127162 | N35: =M35/M$34 -> 0.075 | O35: =O28*O10 -> 0 | P35: =O35/O$34 -> 0 | Q35: =Q28*Q10 -> 1758700 | R35: =Q35/Q$34 -> 0.043 | S35: =S28*S10 -> 1376000 | T35: =S35/S$34 -> 0.043 | U35: =U28*U10 -> 1312227.2 | V35: =U35/U$34 -> 0.043 | W35: =W28*W10 -> 820620 | X35: =W35/W$34 -> 0.094 | Z35: =Z28*Z10 -> 385275000 | AA35: =Z35/Z$34 -> 0.055 | AB35: =AB28*AB10 -> 220000000 | AC35: =AB35/AB$34 -> 0.055 | AD35: =AD28*AD10 -> 20600250 | AE35: =AD35/AD$34 -> 0.055 | AF35: =AF28*AF10 -> 176000000 | AG35: =AF35/AF$34 -> 0.055 | AH35: =AH28*AH10 -> 40625750 | AI35: =AH35/AH$34 -> 0.055 | AJ35: =AJ28*AJ10 -> 219450000 | AK35: =AJ35/AJ$34 -> 0.055 | AL35: =AL28*AL10 -> 40590000 | AM35: =AL35/AL$34 -> 0.055 | AN35: =AN28*AN10 -> 89595000 | AO35: =AN35/AN$34 -> 0.055 | AP35: =AP28*AP10 -> 16500000 | AQ35: =AP35/AP$34 -> 0.055 | AR35: =AR28*AR10 -> 132000000 | AS35: =AR35/AR$34 -> 0.055 | AT35: =AT28*AT10 -> 330000000 | AU35: =AT35/AT$34 -> 0.055 | AV35: =AV28*AV10 -> 165000000 | AW35: =AV35/AV$34 -> 0.055 | AX35: =AX28*AX10 -> 484000000 | AY35: =AX35/AX$34 -> 0.055 | AZ35: =AZ28*AZ10 -> 209000000 | BA35: =AZ35/AZ$34 -> 0.055 | BB35: =BB28*BB10 -> 68750000 | BC35: =BB35/BB$34 -> 0.055 | BD35: =BD28*BD10 -> 209000000 | BE35: =BD35/BD$34 -> 0.055 | BF35: =BF28*BF10 -> 220000000 | BG35: =BF35/BF$34 -> 0.055 | BH35: =BH28*BH10 -> 55000000 | BI35: =BH35/BH$34 -> 0.055 | BJ35: =BJ28*BJ10 -> 220000000 | BK35: =BJ35/BJ$34 -> 0.055 | BL35: =C35+E35+G35+I35+K35+M35+O35+Q35+S35+U35+W35+Z35+AB35+AD35+AF35+AH35+AJ35+AL35+AN35+AP35+AR35+AT35+AV35+AX35+AZ35+BB35+BD35+BF35+BH35+BJ35 -> 3.5673845e+09 | BM35: =BL35/BL$34 -> 0.052949225
B36: '26년 제조원가 | C36: =C29*C10 -> 2.5674379e+09 | D36: =C36/C$34 -> 0.93661311 | E36: =E29*E10 -> 1.6332615e+09 | F36: =E36/E$34 -> 0.91076087 | G36: =G29*G10 -> 1.064009e+09 | H36: =G36/G$34 -> 0.8633034 | I36: =I29*I10 -> 782283637 | J36: =I36/I$34 -> 1 | K36: =K29*K10 -> 3.6241737e+08 | L36: =K36/K$34 -> 0.88961197 | M36: =M29*M10 -> 1.555582e+08 | N36: =M36/M$34 -> 0.9620441 | O36: =O29*O10 -> 118000000 | P36: =O36/O$34 -> 1 | Q36: =Q29*Q10 -> 33858700 | R36: =Q36/Q$34 -> 0.82784108 | S36: =S29*S10 -> 27243420 | T36: =S36/S$34 -> 0.85135688 | U36: =U29*U10 -> 26190573 | V36: =U36/U$34 -> 0.85823142 | W36: =W29*W10 -> 8159825.9 | X36: =W36/W$34 -> 0.93468796 | Z36: =Z29*Z10 -> 6876075000 | AA36: =Z36/Z$34 -> 0.98159529 | AB36: =AB29*AB10 -> 3328000000 | AC36: =AB36/AB$34 -> 0.832 | AD36: =AD29*AD10 -> 324820350 | AE36: =AD36/AD$34 -> 0.86722827 | AF36: =AF29*AF10 -> 2794550000 | AG36: =AF36/AF$34 -> 0.87329687 | AH36: =AH29*AH10 -> 724638250 | AI36: =AH36/AH$34 -> 0.9810306 | AJ36: =AJ29*AJ10 -> 3814450000 | AK36: =AJ36/AJ$34 -> 0.95600251 | AL36: =AL29*AL10 -> 605340000 | AM36: =AL36/AL$34 -> 0.8202439 | AN36: =AN29*AN10 -> 1412795000 | AO36: =AN36/AN$34 -> 0.86727747 | AP36: =AP29*AP10 -> 242000000 | AQ36: =AP36/AP$34 -> 0.80666667 | AR36: =AR29*AR10 -> 2097000000 | AS36: =AR36/AR$34 -> 0.87375 | AT36: =AT29*AT10 -> 5730000000 | AU36: =AT36/AT$34 -> 0.955 | AV36: =AV29*AV10 -> 2865000000 | AW36: =AV36/AV$34 -> 0.955 | AX36: =AX29*AX10 -> 7524000000 | AY36: =AX36/AX$34 -> 0.855 | AZ36: =AZ29*AZ10 -> 3439000000 | BA36: =AZ36/AZ$34 -> 0.905 | BB36: =BB29*BB10 -> 1131250000 | BC36: =BB36/BB$34 -> 0.905 | BD36: =BD29*BD10 -> 3439000000 | BE36: =BD36/BD$34 -> 0.905 | BF36: =BF29*BF10 -> 3420000000 | BG36: =BF36/BF$34 -> 0.855 | BH36: =BH29*BH10 -> 955000000 | BI36: =BH36/BH$34 -> 0.955 | BJ36: =BJ29*BJ10 -> 3620000000 | BK36: =BJ36/BJ$34 -> 0.905 | BL36: =C36+E36+G36+I36+K36+M36+O36+Q36+S36+U36+W36+Z36+AB36+AD36+AF36+AH36+AJ36+AL36+AN36+AP36+AR36+AT36+AV36+AX36+AZ36+BB36+BD36+BF36+BH36+BJ36 -> 6.1121339e+10 | BM36: =BL36/BL$34 -> 0.90719896
B37: '26년 판관비 | C37: =C30*C10 -> 3.3716681e+08 | D37: =C37/C$34 -> 0.123 | E37: =E30*E10 -> 2.2057509e+08 | F37: =E37/E$34 -> 0.123 | G37: =G30*G10 -> 1.5159573e+08 | H37: =G37/G$34 -> 0.123 | I37: =I30*I10 -> 96220887 | J37: =I37/I$34 -> 0.123 | K37: =K30*K10 -> 50108742 | L37: =K37/K$34 -> 0.123 | M37: =M30*M10 -> 19888546 | N37: =M37/M$34 -> 0.123 | O37: =O30*O10 -> 14514000 | P37: =O37/O$34 -> 0.123 | Q37: =Q30*Q10 -> 5030700 | R37: =Q37/Q$34 -> 0.123 | S37: =S30*S10 -> 3936000 | T37: =S37/S$34 -> 0.123 | U37: =U30*U10 -> 3753580.2 | V37: =U37/U$34 -> 0.123 | W37: =W30*W10 -> 1073790 | X37: =W37/W$34 -> 0.123 | Z37: =Z30*Z10 -> 861615000 | AA37: =Z37/Z$34 -> 0.123 | AB37: =AB30*AB10 -> 492000000 | AC37: =AB37/AB$34 -> 0.123 | AD37: =AD30*AD10 -> 46069650 | AE37: =AD37/AD$34 -> 0.123 | AF37: =AF30*AF10 -> 393600000 | AG37: =AF37/AF$34 -> 0.123 | AH37: =AH30*AH10 -> 90853950 | AI37: =AH37/AH$34 -> 0.123 | AJ37: =AJ30*AJ10 -> 490770000 | AK37: =AJ37/AJ$34 -> 0.123 | AL37: =AL30*AL10 -> 90774000 | AM37: =AL37/AL$34 -> 0.123 | AN37: =AN30*AN10 -> 200367000 | AO37: =AN37/AN$34 -> 0.123 | AP37: =AP30*AP10 -> 36900000 | AQ37: =AP37/AP$34 -> 0.123 | AR37: =AR30*AR10 -> 295200000 | AS37: =AR37/AR$34 -> 0.123 | AT37: =AT30*AT10 -> 738000000 | AU37: =AT37/AT$34 -> 0.123 | AV37: =AV30*AV10 -> 369000000 | AW37: =AV37/AV$34 -> 0.123 | AX37: =AX30*AX10 -> 1082400000 | AY37: =AX37/AX$34 -> 0.123 | AZ37: =AZ30*AZ10 -> 467400000 | BA37: =AZ37/AZ$34 -> 0.123 | BB37: =BB30*BB10 -> 153750000 | BC37: =BB37/BB$34 -> 0.123 | BD37: =BD30*BD10 -> 467400000 | BE37: =BD37/BD$34 -> 0.123 | BF37: =BF30*BF10 -> 492000000 | BG37: =BF37/BF$34 -> 0.123 | BH37: =BH30*BH10 -> 123000000 | BI37: =BH37/BH$34 -> 0.123 | BJ37: =BJ30*BJ10 -> 492000000 | BK37: =BJ37/BJ$34 -> 0.123 | BL37: =C37+E37+G37+I37+K37+M37+O37+Q37+S37+U37+W37+Z37+AB37+AD37+AF37+AH37+AJ37+AL37+AN37+AP37+AR37+AT37+AV37+AX37+AZ37+BB37+BD37+BF37+BH37+BJ37 -> 8.2869635e+09 | BM37: =BL37/BL$34 -> 0.123
B38: '26년 영업이익 | C38: =C34-C36-C37 -> -1.6341109e+08 | D38: =C38/C$34 -> -0.059613115 | E38: =E34-E36-E37 -> -60543146 | F38: =E38/E$34 -> -0.03376087 | G38: =G34-G36-G37 -> 16880864 | H38: =G38/G$34 -> 0.013696601 | I38: =I34-I36-I37 -> -96220887 | J38: =I38/I$34 -> -0.123 | K38: =K34-K36-K37 -> -5137965.4 | L38: =K38/K$34 -> -0.012611966 | M38: =M34-M36-M37 -> -13751248 | N38: =M38/M$34 -> -0.085044096 | O38: =O34-O36-O37 -> -14514000 | P38: =O38/O$34 -> -0.123 | Q38: =Q34-Q36-Q37 -> 2010600 | R38: =Q38/Q$34 -> 0.049158924 | S38: =S34-S36-S37 -> 820580 | T38: =S38/S$34 -> 0.025643125 | U38: =U34-U36-U37 -> 572758.99 | V38: =U38/U$34 -> 0.018768576 | W38: =W34-W36-W37 -> -503615.88 | X38: =W38/W$34 -> -0.057687959 | Z38: =Z34-Z36-Z37 -> -732690000 | AA38: =Z38/Z$34 -> -0.10459529 | AB38: =AB34-AB36-AB37 -> 180000000 | AC38: =AB38/AB$34 -> 0.045 | AD38: =AD34-AD36-AD37 -> 3660000 | AE38: =AD38/AD$34 -> 0.0097717261 | AF38: =AF34-AF36-AF37 -> 11850000 | AG38: =AF38/AF$34 -> 0.003703125 | AH38: =AH34-AH36-AH37 -> -76842200 | AI38: =AH38/AH$34 -> -0.1040306 | AJ38: =AJ34-AJ36-AJ37 -> -315220000 | AK38: =AJ38/AJ$34 -> -0.079002506 | AL38: =AL34-AL36-AL37 -> 41886000 | AM38: =AL38/AL$34 -> 0.056756098 | AN38: =AN34-AN36-AN37 -> 15838000 | AO38: =AN38/AN$34 -> 0.0097225292 | AP38: =AP34-AP36-AP37 -> 21100000 | AQ38: =AP38/AP$34 -> 0.070333333 | AR38: =AR34-AR36-AR37 -> 7800000 | AS38: =AR38/AR$34 -> 0.00325 | AT38: =AT34-AT36-AT37 -> -468000000 | AU38: =AT38/AT$34 -> -0.078 | AV38: =AV34-AV36-AV37 -> -234000000 | AW38: =AV38/AV$34 -> -0.078 | AX38: =AX34-AX36-AX37 -> 193600000 | AY38: =AX38/AX$34 -> 0.022 | AZ38: =AZ34-AZ36-AZ37 -> -106400000 | BA38: =AZ38/AZ$34 -> -0.028 | BB38: =BB34-BB36-BB37 -> -35000000 | BC38: =BB38/BB$34 -> -0.028 | BD38: =BD34-BD36-BD37 -> -106400000 | BE38: =BD38/BD$34 -> -0.028 | BF38: =BF34-BF36-BF37 -> 88000000 | BG38: =BF38/BF$34 -> 0.022 | BH38: =BH34-BH36-BH37 -> -78000000 | BI38: =BH38/BH$34 -> -0.078 | BJ38: =BJ34-BJ36-BJ37 -> -112000000 | BK38: =BJ38/BJ$34 -> -0.028 | BL38: =C38+E38+G38+I38+K38+M38+O38+Q38+S38+U38+W38+Z38+AB38+AD38+AF38+AH38+AJ38+AL38+AN38+AP38+AR38+AT38+AV38+AX38+AZ38+BB38+BD38+BF38+BH38+BJ38 -> -2.0346153e+09 | BM38: =BL38/BL$34 -> -0.030198961
Z39: =Z35+Z37+Z38 -> 514200000
B40: 3. '26년 계획대비 차이
B41: 구분 | C41: '26년 계획(A) | E41: '26년 예상(B) | G41: 차이 B-A | H41: B/A-1
B42: '26년 매출반영 | C42: 44247000000 | D42: =C42/C$42 -> 1 | E42: =BL34 -> 67373686852 | F42: =E42/E$42 -> 1 | G42: =E42-C42 -> 23126686852 | H42: =E42/C42-1 -> 0.52267243
...

Sheet 수처리
B2: 수처리
C4: '25년 수주잔고 => | L4: '26년 수주 =>
B5: 1. 프로젝트별 세부내역 | AA5: (단위 : 원/VAT별도)
B6: 구분 | C6: 에코프로머티리얼즈 / 포항 4캠퍼스 머티리얼즈 통합폐수처리장 | E6: 에코프로머티리얼즈 / 포항 4캠퍼스 통합폐수처리장 및 EWT 운영관리 | G6: 에코프로이노베이션 / 증발농축 2단계 및 리튬용액 배관분리 공사 | I6: BM HU / [EA1] 비공정 폐수 증발농축 시스템 납품 | L6: [BMHU] 헝가리 EA1 Gray Water 처리 설비 | N6: [BM] 포항 CAM9 LFP 공정 수/폐수처리설비 공사 | P6: [덴티움] 암모니아 회수설비 공사 | R6: [한화오션] 여수 집단에너지 폐수처리설비 공사 | T6: [MAT] 포항 CPM1 폐수처리장 증설 공사 | V6: [에스아이머티리얼즈] 실리콘 폐수 농축 설비 공사 | X6: [BMHU] 헝가리 EA1 세탁폐수 처리 설비 설치 공사 | Z6: 합 계
B7: 계약예정일 | C7: 23년 6월 - 26년 4월 | E7: 25년 11월 - 26년 11월 | G7: 24년 10월 - 26년 4월 | I7: 24년 10월 - 26년 4월 | L7: 26년 9월 | N7: 26년 9월 | P7: 26년 8월 | R7: 26년 9월 | T7: 26년 10월 | V7: 26년 7월 | X7: 26년 6월
B8: 계약예정금액 | C8: 2345013300 | D8: =C8/C$8 -> 1 | E8: 1449708150 | F8: =E8/E$8 -> 1 | G8: 998832594 | H8: =G8/G$8 -> 1 | I8: 10988576 | J8: =I8/I$8 -> 1 | L8: 7000000000 | M8: =L8/L$8 -> 1 | N8: 3000000000 | O8: =N8/N$8 -> 1 | P8: 1750000000 | Q8: =P8/P$8 -> 1 | R8: 8000000000 | S8: =R8/R$8 -> 1 | T8: 8000000000 | U8: =T8/T$8 -> 1 | V8: 4000000000 | W8: =V8/V$8 -> 1 | X8: 1034550000 | Y8: =X8/X$8 -> 1 | Z8: =C8+E8+G8+I8+L8+N8+P8+R8+T8+V8+X8 -> 37589092620
B9: 최대 Nego 금액 | L9: 6300000000 | M9: =L9/L$8 -> 0.9 | N9: 2700000000 | O9: =N9/N$8 -> 0.9 | P9: 1575000000 | Q9: =P9/P$8 -> 0.9 | R9: 7200000000 | S9: =R9/R$8 -> 0.9 | T9: 7200000000 | U9: =T9/T$8 -> 0.9 | V9: 3600000000 | W9: =V9/V$8 -> 0.9 | X9: 931095000 | Y9: =X9/X$8 -> 0.9 | Z9: =C9+E9+G9+I9+L9+N9+P9+R9+T9+V9+X9 -> 29506095000
B10: 프로젝트 진행률 (2026년 기준) | C10: 1 | E10: 1 | G10: 1 | I10: 1 | L10: 0.3 | N10: 0.3 | P10: 0.4 | R10: 0.3 | T10: 0.4 | V10: 0.3 | X10: 1
B11: 토목 | D11: =C11/C$8 -> 0 | F11: =E11/E$8 -> 0 | H11: =G11/G$8 -> 0 | J11: =I11/I$8 -> 0 | L11: 1.8754585e+09 | M11: =L11/L$8 -> 0.26792264 | O11: =N11/N$8 -> 0 | Q11: =P11/P$8 -> 0 | S11: =R11/R$8 -> 0 | U11: =T11/T$8 -> 0 | W11: =V11/V$8 -> 0 | X11: 57678885 | Y11: =X11/X$8 -> 0.055752632
B12: 기계 | D12: =C12/C$8 -> 0 | F12: =E12/E$8 -> 0 | H12: =G12/G$8 -> 0 | J12: =I12/I$8 -> 0 | L12: 1.10561e+09 | M12: =L12/L$8 -> 0.15794429 | N12: 1200000000 | O12: =N12/N$8 -> 0.4 | P12: 898832000 | Q12: =P12/P$8 -> 0.51361829 | R12: 2380000000 | S12: =R12/R$8 -> 0.2975 | T12: 4096000000 | U12: =T12/T$8 -> 0.512 | V12: 2600000000 | W12: =V12/V$8 -> 0.65 | X12: 214099875 | Y12: =X12/X$8 -> 0.20694976
B13: 전기 | D13: =C13/C$8 -> 0 | F13: =E13/E$8 -> 0 | H13: =G13/G$8 -> 0 | J13: =I13/I$8 -> 0 | L13: 5.3107934e+08 | M13: =L13/L$8 -> 0.075868477 | N13: 420000000 | O13: =N13/N$8 -> 0.14 | P13: 143952000 | Q13: =P13/P$8 -> 0.082258286 | R13: 1292000000 | S13: =R13/R$8 -> 0.1615 | T13: 1200000000 | U13: =T13/T$8 -> 0.15 | V13: 160000000 | W13: =V13/V$8 -> 0.04 | X13: 94144545 | Y13: =X13/X$8 -> 0.091000478
B14: 계장 | D14: =C14/C$8 -> 0 | F14: =E14/E$8 -> 0 | H14: =G14/G$8 -> 0 | J14: =I14/I$8 -> 0 | L14: 0 | M14: =L14/L$8 -> 0 | O14: =N14/N$8 -> 0 | Q14: =P14/P$8 -> 0 | S14: =R14/R$8 -> 0 | U14: =T14/T$8 -> 0 | W14: =V14/V$8 -> 0 | Y14: =X14/X$8 -> 0
B15: 배관 | D15: =C15/C$8 -> 0 | F15: =E15/E$8 -> 0 | H15: =G15/G$8 -> 0 | J15: =I15/I$8 -> 0 | L15: 6.5265867e+08 | M15: =L15/L$8 -> 0.093236953 | N15: 650000000 | O15: =N15/N$8 -> 0.21666667 | P15: 128800000 | Q15: =P15/P$8 -> 0.0736 | R15: 2366400000 | S15: =R15/R$8 -> 0.2958 | T15: 1040000000 | U15: =T15/T$8 -> 0.13 | V15: 180000000 | W15: =V15/V$8 -> 0.045 | X15: 65319210 | Y15: =X15/X$8 -> 0.063137799
B16: 회전기기 | D16: =C16/C$8 -> 0 | F16: =E16/E$8 -> 0 | H16: =G16/G$8 -> 0 | J16: =I16/I$8 -> 0 | L16: 0 | M16: =L16/L$8 -> 0 | O16: =N16/N$8 -> 0 | Q16: =P16/P$8 -> 0 | S16: =R16/R$8 -> 0 | U16: =T16/T$8 -> 0 | W16: =V16/V$8 -> 0 | Y16: =X16/X$8 -> 0
B17: 열교환기 | D17: =C17/C$8 -> 0 | F17: =E17/E$8 -> 0 | H17: =G17/G$8 -> 0 | J17: =I17/I$8 -> 0 | L17: 0 | M17: =L17/L$8 -> 0 | O17: =N17/N$8 -> 0 | Q17: =P17/P$8 -> 0 | S17: =R17/R$8 -> 0 | U17: =T17/T$8 -> 0 | W17: =V17/V$8 -> 0 | Y17: =X17/X$8 -> 0
B18: 촉매 | D18: =C18/C$8 -> 0 | F18: =E18/E$8 -> 0 | H18: =G18/G$8 -> 0 | J18: =I18/I$8 -> 0 | L18: 0 | M18: =L18/L$8 -> 0 | O18: =N18/N$8 -> 0 | Q18: =P18/P$8 -> 0 | S18: =R18/R$8 -> 0 | U18: =T18/T$8 -> 0 | W18: =V18/V$8 -> 0 | Y18: =X18/X$8 -> 0
B19: 분석기 | D19: =C19/C$8 -> 0 | F19: =E19/E$8 -> 0 | H19: =G19/G$8 -> 0 | J19: =I19/I$8 -> 0 | L19: 0 | M19: =L19/L$8 -> 0 | O19: =N19/N$8 -> 0 | Q19: =P19/P$8 -> 0 | S19: =R19/R$8 -> 0 | U19: =T19/T$8 -> 0 | W19: =V19/V$8 -> 0 | Y19: =X19/X$8 -> 0
B20: 버너 | D20: =C20/C$8 -> 0 | F20: =E20/E$8 -> 0 | H20: =G20/G$8 -> 0 | J20: =I20/I$8 -> 0 | L20: 0 | M20: =L20/L$8 -> 0 | O20: =N20/N$8 -> 0 | Q20: =P20/P$8 -> 0 | S20: =R20/R$8 -> 0 | U20: =T20/T$8 -> 0 | W20: =V20/V$8 -> 0 | Y20: =X20/X$8 -> 0
B21: Filter | D21: =C21/C$8 -> 0 | F21: =E21/E$8 -> 0 | H21: =G21/G$8 -> 0 | J21: =I21/I$8 -> 0 | L21: 0 | M21: =L21/L$8 -> 0 | O21: =N21/N$8 -> 0 | Q21: =P21/P$8 -> 0 | S21: =R21/R$8 -> 0 | U21: =T21/T$8 -> 0 | W21: =V21/V$8 -> 0 | Y21: =X21/X$8 -> 0
B22: 활성탄 | D22: =C22/C$8 -> 0 | F22: =E22/E$8 -> 0 | H22: =G22/G$8 -> 0 | J22: =I22/I$8 -> 0 | L22: 0 | M22: =L22/L$8 -> 0 | O22: =N22/N$8 -> 0 | Q22: =P22/P$8 -> 0 | S22: =R22/R$8 -> 0 | U22: =T22/T$8 -> 0 | W22: =V22/V$8 -> 0 | Y22: =X22/X$8 -> 0
B23: 방음룸 | D23: =C23/C$8 -> 0 | F23: =E23/E$8 -> 0 | H23: =G23/G$8 -> 0 | J23: =I23/I$8 -> 0 | L23: 0 | M23: =L23/L$8 -> 0 | O23: =N23/N$8 -> 0 | Q23: =P23/P$8 -> 0 | S23: =R23/R$8 -> 0 | U23: =T23/T$8 -> 0 | W23: =V23/V$8 -> 0 | Y23: =X23/X$8 -> 0
B24: 안전관리비 | D24: =C24/C$8 -> 0 | F24: =E24/E$8 -> 0 | H24: =G24/G$8 -> 0 | J24: =I24/I$8 -> 0 | L24: 41466855 | M24: =L24/L$8 -> 0.0059238364 | N24: 46367000 | O24: =N24/N$8 -> 0.015455667 | P24: 24309522 | Q24: =P24/P$8 -> 0.013891155 | R24: 1.1974448e+08 | S24: =R24/R$8 -> 0.01496806 | T24: 128633600 | U24: =T24/T$8 -> 0.0160792 | V24: 41657333 | W24: =V24/V$8 -> 0.010414333 | X24: 15000000 | Y24: =X24/X$8 -> 0.014499058
B25: 외주용역 | D25: =C25/C$8 -> 0 | F25: =E25/E$8 -> 0 | H25: =G25/G$8 -> 0 | J25: =I25/I$8 -> 0 | L25: 5.7979549e+08 | M25: =L25/L$8 -> 0.082827927 | N25: 60000000 | O25: =N25/N$8 -> 0.02 | P25: 50000000 | Q25: =P25/P$8 -> 0.028571429 | R25: 40000000 | S25: =R25/R$8 -> 0.005 | T25: 128000000 | U25: =T25/T$8 -> 0.016 | V25: 20000000 | W25: =V25/V$8 -> 0.005 | X25: 255595230 | Y25: =X25/X$8 -> 0.24705933
B26: 기타 | D26: =C26/C$8 -> 0 | F26: =E26/E$8 -> 0 | H26: =G26/G$8 -> 0 | J26: =I26/I$8 -> 0 | L26: 1.1247884e+09 | M26: =L26/L$8 -> 0.16068406 | N26: 88000000 | O26: =N26/N$8 -> 0.029333333 | P26: 122000000 | Q26: =P26/P$8 -> 0.069714286 | R26: 650000000 | S26: =R26/R$8 -> 0.08125 | T26: 240000000 | U26: =T26/T$8 -> 0.03 | V26: 125000000 | W26: =V26/V$8 -> 0.03125 | X26: 131239830 | Y26: =X26/X$8 -> 0.12685692
B27: 제조직접원가 | C27: =C8*D27 -> 2.0568393e+09 | D27: =D29-D28 -> 0.877112 | E27: =E8*F27 -> 1.1540468e+09 | F27: =F29-F28 -> 0.79605455 | G27: =G8*H27 -> 8.5327976e+08 | H27: =H29-H28 -> 0.85427705 | I27: =I8*J27 -> 8581682.5 | J27: =J29-J28 -> 0.78096402 | L27: =SUM(L11:L26) -> 5.9108573e+09 | M27: =L27/L$8 -> 0.84440818 | N27: =SUM(N11:N26) -> 2464367000 | O27: =N27/N$8 -> 0.82145567 | P27: =SUM(P11:P26) -> 1.3678935e+09 | Q27: =P27/P$8 -> 0.78165344 | R27: =SUM(R11:R26) -> 6848144480 | S27: =R27/R$8 -> 0.85601806 | T27: =SUM(T11:T26) -> 6832633600 | U27: =T27/T$8 -> 0.8540792 | V27: =SUM(V11:V26) -> 3.1266573e+09 | W27: =V27/V$8 -> 0.78166433 | X27: =SUM(X11:X26) -> 833077575 | Y27: =X27/X$8 -> 0.80525598 | Z27: =C27+E27+G27+I27+L27+N27+P27+R27+T27+V27+X27 -> 3.1456378e+10
B28: 제조간접원가 | C28: =C8*D28 -> 30485173 | D28: 0.013 | E28: =E8*F28 -> 69585991 | F28: 0.048 | G28: =G8*H28 -> 22973150 | H28: 0.023 | I28: =I8*J28 -> 472508.77 | J28: 0.043 | L28: =L8*M28 -> 518000000 | M28: 0.074 | N28: =N8*O28 -> 222000000 | O28: 0.074 | P28: =P8*Q28 -> 129500000 | Q28: 0.074 | R28: =R8*S28 -> 592000000 | S28: 0.074 | T28: =T8*U28 -> 592000000 | U28: 0.074 | V28: =V8*W28 -> 296000000 | W28: 0.074 | X28: =X8*Y28 -> 76556700 | Y28: 0.074 | Z28: =C28+E28+G28+I28+L28+N28+P28+R28+T28+V28+X28 -> 2.5495735e+09
B29: 제조원가 | C29: =C8*D29 -> 2.0873245e+09 | D29: 0.890112 | E29: =E8*F29 -> 1.2236328e+09 | F29: 0.84405455 | G29: =G8*H29 -> 8.7625291e+08 | H29: 0.87727705 | I29: =I8*J29 -> 9054191.3 | J29: 0.82396402 | L29: =L27+L28 -> 6.4288573e+09 | M29: =L29/L$8 -> 0.91840818 | N29: =N27+N28 -> 2686367000 | O29: =N29/N$8 -> 0.89545567 | P29: =P27+P28 -> 1.4973935e+09 | Q29: =P29/P$8 -> 0.85565344 | R29: =R27+R28 -> 7440144480 | S29: =R29/R$8 -> 0.93001806 | T29: =T27+T28 -> 7424633600 | U29: =T29/T$8 -> 0.9280792 | V29: =V27+V28 -> 3.4226573e+09 | W29: =V29/V$8 -> 0.85566433 | X29: =X27+X28 -> 909634275 | Y29: =X29/X$8 -> 0.87925598 | Z29: =C29+E29+G29+I29+L29+N29+P29+R29+T29+V29+X29 -> 3.4005952e+10
B30: 판관비 | C30: =C8*D30 -> 3.1423178e+08 | D30: 0.134 | E30: =E8*F30 -> 1.9426089e+08 | F30: 0.134 | G30: =G8*H30 -> 1.3384357e+08 | H30: 0.134 | I30: =I8*J30 -> 1472469.2 | J30: 0.134 | L30: =L8*M30 -> 938000000 | M30: 0.134 | N30: =N8*O30 -> 402000000 | O30: 0.134 | P30: =P8*Q30 -> 234500000 | Q30: 0.134 | R30: =R8*S30 -> 1.072e+09 | S30: 0.134 | T30: =T8*U30 -> 1.072e+09 | U30: 0.134 | V30: =V8*W30 -> 5.36e+08 | W30: 0.134 | X30: =X8*Y30 -> 138629700 | Y30: 0.134 | Z30: =C30+E30+G30+I30+L30+N30+P30+R30+T30+V30+X30 -> 5.0369384e+09
B31: 영업이익 | C31: =C8-C29-C30 -> -56542971 | D31: =C31/C$8 -> -0.024112005 | E31: =E8-E29-E30 -> 31814504 | F31: =E31/E$8 -> 0.021945455 | G31: =G8-G29-G30 -> -11263881 | H31: =G31/G$8 -> -0.011277046 | I31: =I8-I29-I30 -> 461915.53 | J31: =I31/I$8 -> 0.042035978 | L31: =L8-L29-L30 -> -3.6685726e+08 | M31: =L31/L$8 -> -0.052408181 | N31: =N8-N29-N30 -> -88367000 | O31: =N31/N$8 -> -0.029455667 | P31: =P8-P29-P30 -> 18106478 | Q31: =P31/P$8 -> 0.010346559 | R31: =R8-R29-R30 -> -5.1214448e+08 | S31: =R31/R$8 -> -0.06401806 | T31: =T8-T29-T30 -> -4.966336e+08 | U31: =T31/T$8 -> -0.0620792 | V31: =V8-V29-V30 -> 41342667 | W31: =V31/V$8 -> 0.010335667 | X31: =X8-X29-X30 -> -13713975 | Y31: =X31/X$8 -> -0.013255981 | Z31: =C31+E31+G31+I31+L31+N31+P31+R31+T31+V31+X31 -> -1.4537976e+09
B33: 2. '26년 프로젝트별 손익
B34: '26년 매출반영 | C34: =C8*C10 -> 2345013300 | D34: =C34/C$34 -> 1 | E34: =E8*E10 -> 1449708150 | F34: =E34/E$34 -> 1 | G34: =G8*G10 -> 998832594 | H34: =G34/G$34 -> 1 | I34: =I8*I10 -> 10988576 | J34: =I34/I$34 -> 1 | L34: =L8*L10 -> 2100000000 | M34: =L34/L$34 -> 1 | N34: =N8*N10 -> 900000000 | O34: =N34/N$34 -> 1 | P34: =P8*P10 -> 700000000 | Q34: =P34/P$34 -> 1 | R34: =R8*R10 -> 2400000000 | S34: =R34/R$34 -> 1 | T34: =T8*T10 -> 3200000000 | U34: =T34/T$34 -> 1 | V34: =V8*V10 -> 1200000000 | W34: =V34/V$34 -> 1 | X34: =X8*X10 -> 1034550000 | Y34: =X34/X$34 -> 1 | Z34: =C34+E34+G34+I34+L34+N34+P34+R34+T34+V34+X34 -> 16339092620 | AA34: =Z34/Z$34 -> 1
B35: '26년 제조간접원가 | C35: =C28*C10 -> 30485173 | D35: =C35/C$34 -> 0.013 | E35: =E28*E10 -> 69585991 | F35: =E35/E$34 -> 0.048 | G35: =G28*G10 -> 22973150 | H35: =G35/G$34 -> 0.023 | I35: =I28*I10 -> 472508.77 | J35: =I35/I$34 -> 0.043 | L35: =L28*L10 -> 155400000 | M35: =L35/L$34 -> 0.074 | N35: =N28*N10 -> 66600000 | O35: =N35/N$34 -> 0.074 | P35: =P28*P10 -> 51800000 | Q35: =P35/P$34 -> 0.074 | R35: =R28*R10 -> 177600000 | S35: =R35/R$34 -> 0.074 | T35: =T28*T10 -> 236800000 | U35: =T35/T$34 -> 0.074 | V35: =V28*V10 -> 88800000 | W35: =V35/V$34 -> 0.074 | X35: =X28*X10 -> 76556700 | Y35: =X35/X$34 -> 0.074 | Z35: =C35+E35+G35+I35+L35+N35+P35+R35+T35+V35+X35 -> 9.7707352e+08 | AA35: =Z35/Z$34 -> 0.059799742
B36: '26년 제조원가 | C36: =C29*C10 -> 2.0873245e+09 | D36: =C36/C$34 -> 0.890112 | E36: =E29*E10 -> 1.2236328e+09 | F36: =E36/E$34 -> 0.84405455 | G36: =G29*G10 -> 8.7625291e+08 | H36: =G36/G$34 -> 0.87727705 | I36: =I29*I10 -> 9054191.3 | J36: =I36/I$34 -> 0.82396402 | L36: =L29*L10 -> 1.9286572e+09 | M36: =L36/L$34 -> 0.91840818 | N36: =N29*N10 -> 805910100 | O36: =N36/N$34 -> 0.89545567 | P36: =P29*P10 -> 5.9895741e+08 | Q36: =P36/P$34 -> 0.85565344 | R36: =R29*R10 -> 2232043344 | S36: =R36/R$34 -> 0.93001806 | T36: =T29*T10 -> 2969853440 | U36: =T36/T$34 -> 0.9280792 | V36: =V29*V10 -> 1026797200 | W36: =V36/V$34 -> 0.85566433 | X36: =X29*X10 -> 909634275 | Y36: =X36/X$34 -> 0.87925598 | Z36: =C36+E36+G36+I36+L36+N36+P36+R36+T36+V36+X36 -> 1.4668117e+10 | AA36: =Z36/Z$34 -> 0.89773145
B37: '26년 판관비 | C37: =C30*C10 -> 3.1423178e+08 | D37: =C37/C$34 -> 0.134 | E37: =E30*E10 -> 1.9426089e+08 | F37: =E37/E$34 -> 0.134 | G37: =G30*G10 -> 1.3384357e+08 | H37: =G37/G$34 -> 0.134 | I37: =I30*I10 -> 1472469.2 | J37: =I37/I$34 -> 0.134 | L37: =L30*L10 -> 281400000 | M37: =L37/L$34 -> 0.134 | N37: =N30*N10 -> 120600000 | O37: =N37/N$34 -> 0.134 | P37: =P30*P10 -> 93800000 | Q37: =P37/P$34 -> 0.134 | R37: =R30*R10 -> 321600000 | S37: =R37/R$34 -> 0.134 | T37: =T30*T10 -> 4.288e+08 | U37: =T37/T$34 -> 0.134 | V37: =V30*V10 -> 160800000 | W37: =V37/V$34 -> 0.134 | X37: =X30*X10 -> 138629700 | Y37: =X37/X$34 -> 0.134 | Z37: =C37+E37+G37+I37+L37+N37+P37+R37+T37+V37+X37 -> 2.1894384e+09 | AA37: =Z37/Z$34 -> 0.134
B38: '26년 영업이익 | C38: =C34-C36-C37 -> -56542971 | D38: =C38/C$34 -> -0.024112005 | E38: =E34-E36-E37 -> 31814504 | F38: =E38/E$34 -> 0.021945455 | G38: =G34-G36-G37 -> -11263881 | H38: =G38/G$34 -> -0.011277046 | I38: =I34-I36-I37 -> 461915.53 | J38: =I38/I$34 -> 0.042035978 | L38: =L34-L36-L37 -> -1.1005718e+08 | M38: =L38/L$34 -> -0.052408181 | N38: =N34-N36-N37 -> -26510100 | O38: =N38/N$34 -> -0.029455667 | P38: =P34-P36-P37 -> 7242591.4 | Q38: =P38/P$34 -> 0.010346559 | R38: =R34-R36-R37 -> -153643344 | S38: =R38/R$34 -> -0.06401806 | T38: =T34-T36-T37 -> -1.9865344e+08 | U38: =T38/T$34 -> -0.0620792 | V38: =V34-V36-V37 -> 12402800 | W38: =V38/V$34 -> 0.010335667 | X38: =X34-X36-X37 -> -13713975 | Y38: =X38/X$34 -> -0.013255981 | Z38: =C38+E38+G38+I38+L38+N38+P38+R38+T38+V38+X38 -> -5.1846308e+08 | AA38: =Z38/Z$34 -> -0.031731449
B40: 3. '26년 계획대비 차이
B41: 구분 | C41: '26년 계획(A) | E41: '26년 예상(B) | G41: 차이 B-A | H41: B/A-1
B42: '26년 매출반영 | C42: 1.698249e+10 | D42: =C42/C$42 -> 1 | E42: =Z34 -> 16339092620 | F42: =E42/E$42 -> 1 | G42: =E42-C42 -> -6.4339775e+08 | H42: =E42/C42-1 -> -0.037885948
B43: '26년 제조간접원가 | C43: =C42*D43 -> 1.2625385e+09 | D43: 0.074343542 | E43: =Z35 -> 9.7707352e+08 | F43: =E43/E42 -> 0.059799742 | G43: =E43-C43 -> -2.8546496e+08 | H43: =E43/C43-1 -> -0.22610397
B44: '26년 제조원가 | C44: 1.5145215e+10 | D44: =C44/C$42 -> 0.89181357 | E44: =Z36 -> 1.4668117e+10 | F44: =E44/E$42 -> 0.89773145 | G44: =E44-C44 -> -4.7709801e+08 | H44: =E44/C44-1 -> -0.031501567
...

Sheet 장표_Item
B2: 플랜트대기파트 PJT 실행예산 보고 (~4Q 주요 프로젝트)
W5: (단위 : 원/VAT별도)
B6: 구분 | C6: BHI 대만 튱샤오 HRSG SCR PKG | F6: KCL 삼척 화재센터 집진시설 개선 | H6: 에코프로INNO HU LHM8K IPPC | J6: 도레이 구미 CK3 환경설비 | L6: BHI 포스코(포항) LNG복합 | N6: 유한화학(화성) RTO 신규 | P6: 삼천포발전본부 SCR 개선 | R6: 한국소방산업기술원 환경설비 | T6: 한주(울산)_SCR | V6: 동서발전 음성 복합발전
B7: 계약예정일 | D7: 26년 3월 | F7: 26년 2월 | H7: 26년 2월 | J7: 26년 3월 | L7: 26년 3월 | N7: 26년 3월 | P7: 26년 3월 | R7: 26년 7월 | T7: 26년 3월 | V7: 26년 9월
B8: 계약예정금액 | D8: 23800000000 | E8: 1 | F8: 4000000000 | G8: 1 | H8: 374550000 | I8: 1 | J8: 3260000000 | K8: 1 | L8: 6900000000 | M8: 1 | N8: 5300000000 | O8: 1 | P8: 2460000000 | Q8: 1 | R8: 1629000000 | S8: 1 | T8: 3000000000 | U8: 1 | V8: 8000000000 | W8: 1
B9: 기계 | D9: 3300000000 | E9: =D9/$D$8 -> 0.13865546 | F9: 1020000000 | G9: =F9/$F$8 -> 0.255 | H9: 140669100 | I9: =H9/$H$8 -> 0.37556828 | J9: 1710000000 | K9: =J9/$J$8 -> 0.52453988 | L9: 2200000000 | M9: =L9/$L$8 -> 0.31884058 | N9: 3160000000 | O9: =N9/$N$8 -> 0.59622642 | P9: 1520000000 | Q9: =P9/$P$8 -> 0.61788618 | R9: =635000000+239000000 -> 874000000 | S9: =R9/$R$8 -> 0.53652548 | T9: 1900000000 | U9: =T9/$T$8 -> 0.63333333 | V9: 2300000000 | W9: =V9/$V$8 -> 0.2875
C10: Catalyst Support and Sealing Material
C11: Ammonia Injection Grid with Support
C12: Piping Work
C13: Ammonia Air Mixer
C14: Ammonia Injection Nozzle
B15: 전기 | D15: 110000000 | E15: =D15/$D$8 -> 0.0046218487 | F15: 214000000 | G15: =F15/$F$8 -> 0.0535 | H15: 49995000 | I15: =H15/$H$8 -> 0.13348018 | J15: 387000000 | K15: =J15/$J$8 -> 0.11871166 | L15: 380000000 | M15: =L15/$L$8 -> 0.055072464 | O15: =N15/$N$8 -> 0 | P15: 220000000 | Q15: =P15/$P$8 -> 0.089430894 | R15: 218000000 | S15: =R15/$R$8 -> 0.13382443 | T15: 220000000 | U15: =T15/$T$8 -> 0.073333333 | V15: 410000000 | W15: =V15/$V$8 -> 0.05125
C16: Instrument Cabinet
C17: Relevant Logic & Loop for DCS Control
C18: Junction Box
C19: Local Operating Panel for Dilution Air Blower
C20: Field Work & Material on AFCU Skid
C21: Junction Box on AFCU Skid
C22: PDP
C23: PLC Control Panel
B24: 계장 | D24: 350000000 | E24: =D24/$D$8 -> 0.014705882 | G24: =F24/$F$8 -> 0 | I24: =H24/$H$8 -> 0 | K24: =J24/$J$8 -> 0 | L24: 310000000 | M24: =L24/$L$8 -> 0.044927536 | O24: =N24/$N$8 -> 0 | Q24: =P24/$P$8 -> 0 | S24: =R24/$R$8 -> 0 | U24: =T24/$T$8 -> 0 | V24: 320000000 | W24: =V24/$V$8 -> 0.04
C25: Flow Control Valve
C26: Flow Transmitter
C27: Flow Transmitter(Vortex)
C28: ON/OFF Valve
C29: Temperature Indicator(With Well)
C30: Temperature Transmitter(With Well)
C31: Manometer
C32: Orifice Plate
C33: Orfice Assembly
C34: Pressure Indicator
C35: Pressure Transmitter
C36: Ammonia Detector Incl. Horn & Beacon
