Workbook
Name ____P10: #REF!
Name ____P11: #REF!
Name ____P12: #REF!
Name ____P13: #REF!
Name ____P14: #REF!
Name ____P15: #REF!
Name ____P16: #REF!
Name ____P17: #REF!
Name ____P7: #REF!
Name ____P8: #REF!
Name ____P9: #REF!
Name ____PH1: #REF!
Name __AHU2: [0]!__AHU2
Name __AHU222: [0]!__AHU222
Name __AHU3: [0]!__AHU3
Name __ELL45: #REF!
Name __ELL90: #REF!
Name __MD1: '[2]할증 '!$B$8
Name __MD2: '[2]할증 '!$B$9
Name __NEW1: ROUND([3]!__NEW1*0.0254,3)
Name __p1: #REF!
Name __P10: #REF!
Name __P11: #REF!
Name __P12: #REF!
Name __P13: #REF!
Name __P14: #REF!
Name __P15: #REF!
Name __P16: #REF!
Name __P17: #REF!
Name __p2: #REF!
Name __p3: #REF!
Name __P4: #REF!
Name __P5: #REF!
Name __P6: #REF!
Name __P7: #REF!
Name __P8: #REF!
Name __P9: #REF!
Name __PH1: #REF!
Name __RE100: #REF!
Name __RE104: #REF!
Name __RE112: #REF!
Name __RE26: #REF!
Name __RE28: #REF!
Name __RE30: #REF!
Name __RE32: #REF!
Name __RE34: #REF!
Name __RE36: #REF!
Name __RE38: #REF!
Name __RE40: #REF!
Name __RE42: #REF!
Name __RE44: #REF!
Name __RE48: #REF!
Name __RE52: #REF!
Name __RE56: #REF!
Name __RE60: #REF!
Name __RE64: #REF!
Name __RE68: #REF!
Name __RE72: #REF!
Name __RE76: #REF!
Name __RE80: #REF!

Sheet 갑지
K1: 제 R241030-01H호
A2: 見 積 書
B4: 작성일자 : 2025-08-20
B6: 통영에코파워 | E6: 귀중
B8: 아래와 같이 견적합니다
B10: 프로젝트 :통영에코파워 SCR 성능개선 (Direct Injection Type)
B12: 合計金額 : | D12: ="一金 "& NUMBERSTRING(ROUNDDOWN(J42,-5),1)&"원整" -> #REF!
D14: ="₩ " &TEXT(J42,"#,###,000,000" ) & " " -> #REF!
B16: 지불조건 : | D16: 추후협의
B18: No. | C18: 名 稱 DESCRIPTION | E18: 規 格 Specification | G18: 數量 Q'ty | H18: 單位 Unit | I18: 單價 Price | J18: 金 額 Amount
B20: =을지!A5 -> ■ 통영에코파워 SCR 환경설비 개선 제안 (Direct Injection System)
C21: 직접분사 설비 X HRSG 2기 | G21: 1 | H21: LOT | I21: =공사원가내역서!G35 -> #REF! | J21: =I21 -> #REF!
C42: TOTAL PRICE | E42: VAT 별도 | I42: 백만단위절사 | J42: =J21 -> #REF! | N42: 1330000000

Sheet 공사원가내역서
A3: =갑지!B10 -> 프로젝트 :통영에코파워 SCR 성능개선 (Direct Injection Type)
A4: 번호 | B4: 구 분 | C4: 항 목 | D4: 수 량 | E4: 단위 | F4: 단 가 | G4: 금 액 | H4: 비 고
A6: 1. | B6: 직접공사비
A7: 1) | B7: 재료비 | C7: 재료비 (완제품가액 포함) | D7: 1 | E7: Lot | F7: =을지!H109 -> 522385000 | G7: =D7*F7 -> 522385000
A8: 소 계 | G8: =SUM(G7:G7) -> 522385000
A9: 2) | B9: 노무비 | C9: 직접노무비 | D9: 1 | E9: Lot | F9: =을지!J109 -> 93000000 | G9: =D9*F9 -> 93000000
A10: 소 계 | G10: =G9 -> 93000000
A11: 3) | B11: 경비 | C11: 경비 | D11: 1 | E11: Lot | F11: =을지!L109 -> 316255000 | G11: =D11*F11 -> 316255000
A12: 소 계 | G12: =G11 -> 316255000
A13: 직 접 공 사 비 계 (1) | G13: =G8+G10+G12 -> 931640000
A14: 2. | B14: 간접공사비
A15: 1) | B15: 간접노무비 | C15: 직접노무비의 | D15: =IF(G13<1000000000,16.5,IF(AND(1000000000<=G13,G13<5000000000),16.2,IF(AND(5000000000<=G13,G13<30000000000),16.3,IF(AND(30000000000<=G13,G13<100000000000),15.7,IF(G13>=100000000000,15.7,0))))) -> 16.5 | E15: % | G15: =G10*D15% -> 15345000
A16: 2) | B16: 산업재해보상보험료 | C16: 노무비의 | D16: 3.56 | E16: % | G16: =(G10+G15)*D16% -> 3857082
A17: 3) | B17: 고용보험료 | C17: 노무비의 | D17: =IF(G13*1.1<14000000000,1.01,IF(G13*1.1<22000000000,1.02,IF(G13*1.1<37000000000,1.03,IF(G13*1.1<57000000000,1.06,IF(G13*1.1<90000000000,1.13,IF(G13*1.1<140000000000,1.3,IF(G13*1.1>=140000000000,1.57,0))))))) -> 1.01 | E17: % | G17: =(G10+G15)*D17% -> 1094284.5
A18: 4) | B18: 국민건강보험료 | C18: 직접노무비의 | D18: 3.545 | E18: % | G18: =G10*D18% -> 3296850
A19: 5) | B19: 국민연금보험료 | C19: 직접노무비의 | D19: 4.5 | E19: % | G19: =G10*D19% -> 4185000
A20: 6) | B20: 노인장기요양보험료 | C20: 건강보험료의 | D20: 12.95 | E20: % | G20: =G18*D20% -> 426942.08
A21: 7) | B21: 산업안전보건관리비 | C21: (재료비+직접노무비+완제품가액)×요율 + 기초액과 ((재료비+직접노무비)×요율 + 기초액)×1.2 중 작은 금액 | D21: =IF(G8+G10<500000000,3.15,IF(G8+G10<5000000000,2.53,IF(G8+G10<80000000000,2.6,IF(G8+G10>=80000000000,2.73,0)))) -> 2.53 | E21: % | G21: =IF((G8+G10)*D21%+H21*1000>((G8+G10-G34)*D21%+H21*1000)*1.2,((G8+G10-G34)*D21%+H21*1000)*1.2,(G8+G10)*D21%+H21*1000) -> 18869240 | H21: =IF(AND(500000000<=G8+G10,5000000000>G8+G10),3300,0) -> 3300
A22: 8) | B22: 환경보전비 | C22: 직접공사비의 | D22: 0.4 | E22: % | G22: =G13*D22% -> 3726560
A23: 9) | B23: 퇴직공제부금비 | C23: 직접노무비의 | D23: =IF((G13)*1.1>5000000000,2.3,0) -> 0 | E23: % | G23: =G10*D23% -> 0
A24: 10) | B24: 하도급대금지급보증 수수료 | C24: 직접공사비의 | D24: =IF(G13*1.1<5000000000,0.081,IF(G13*1.1<10000000000,0.08,IF(G13*1.1<30000000000,0.075,IF(G13*1.1>=30000000000,0.071,0)))) -> 0.081 | E24: % | G24: =G13*D24% -> 754628.4
A25: 11) | B25: 건설기계대여대금 지급보증서 발급비 | C25: 직접공사비의 | D25: 0.16 | E25: % | G25: =G13*D25% -> 1490624
A28: 12) | B28: 기타경비 | C28: (재료비 + 노무비)의 | D28: =IF(G13<1000000000,5.2,IF(G13<5000000000,5.3,IF(G13<30000000000,5.7,IF(G13<100000000000,6,IF(G13>=100000000000,6.1,0))))) -> 5.2 | E28: % | G28: =(G8+G10+G15)*D28% -> 32797960
A29: 13) | B29: 공사이행보증수수료 | C29: 선급금보증, 계약이행보증, 하자이행보증 | D29: - | E29: - | G29: =#REF! -> #REF!
A30: 간 접 공 사 비 계 (2) | G30: =SUM(G15:G29)-2054756 -> #REF!
A31: 순 공 사 원 가 (1+2) | G31: =G30+G13 -> #REF! | J31: =G30+G12 -> #REF!
A32: 3. | B32: 일반관리비 | C32: (재료비 + 노무비 + 경비)의 | D32: =IF(G13<5000000000,8,IF(AND(5000000000<=G13,G13<30000000000),6.5,IF(AND(30000000000<=G13,G13<100000000000),5,IF(G13>=100000000000,4.5,0)))) -> 8 | E32: % | G32: =(G8+G10+G12)*D32% -> 74531200
A33: 4. | B33: 이윤 | C33: (순공사원가 + 일반관리비)의 | D33: 0 | E33: % | G33: =(G31+G32)*D33% -> #REF!
A34: 5. | B34: 완제품 가액
A35: 총 공 사 금 액 (1+2+3+4) | G35: =G31+G32+G33 -> #REF!

Sheet 을지
K1: 제 R200420-01Y호 | S1: 제 R200420-01Y호
M2: ( 단위 : 원)
A3: 품 명 | B3: 규 격 | C3: 수량 | D3: 단위 | E3: 합 계 | G3: 재료비 | I3: 노무비 | K3: 경 비 | M3: 비 고 | O3: 재료비 | Q3: 노무비 | S3: 경 비
E4: 단가 | F4: 금액 | G4: 단가 | H4: 금액 | I4: 단가 | J4: 금액 | K4: 단가 | L4: 금액 | O4: 단가 | Q4: 단가 | S4: 단가
A5: ■ 통영에코파워 SCR 환경설비 개선 제안 (Direct Injection System)
A6: =A15 -> 1. Urea Storage & Supply System | C6: 1 | D6: LOT | E6: =F6/C6 -> 0 | F6: =H6+J6+L6 -> 0 | H6: =H21 -> 0 | J6: =J21 -> 0 | L6: =L21 -> 0 | M6: 기존 설비 사용
A7: =A22 -> 2. SCR and Auxiliary System | C7: 1 | D7: LOT | E7: =F7/C7 -> 0 | F7: =H7+J7+L7 -> 0 | H7: =H32 -> 0 | J7: =J32 -> 0 | L7: =L32 -> 0 | M7: 기존 설비 사용
A8: =A33 -> 3. Urea Injection System | C8: 1 | D8: LOT | E8: =F8/C8 -> 282000000 | F8: =H8+J8+L8 -> 282000000 | H8: =H61 -> 282000000 | J8: =J61 -> 0 | L8: =L61 -> 0
A9: =A62 -> 4. Electric & Instrument | C9: 1 | D9: LOT | E9: =F9/C9 -> 60000000 | F9: =H9+J9+L9 -> 60000000 | H9: =H67 -> 60000000 | J9: =J67 -> 0 | L9: =L67 -> 0
A10: =A68 -> 5. Bulk Material | C10: 1 | D10: LOT | E10: =F10/C10 -> 69000000 | F10: =H10+J10+L10 -> 69000000 | H10: =H87 -> 69000000 | J10: =J87 -> 0 | L10: =L87 -> 0
A11: =A88 -> 6. Miscellaneous | C11: 1 | D11: LOT | E11: =F11/C11 -> 4000000 | F11: =H11+J11+L11 -> 4000000 | H11: =H95 -> 4000000 | J11: =J95 -> 0 | L11: =L95 -> 0
A12: =A96 -> 7. Emgineering Service | C12: 1 | D12: LOT | E12: =F12/C12 -> 95000000 | F12: =H12+J12+L12 -> 95000000 | H12: =H103 -> 0 | J12: =J103 -> 0 | L12: =L103 -> 95000000
A13: =A104 -> 8. Installation Fee | C13: 1 | D13: LOT | F13: =H13+J13+L13 -> 421640000 | H13: =H108 -> 107385000 | J13: =J108 -> 93000000 | L13: =L108 -> 221255000
A14: 총 공 사 비 합 계 | F14: =SUM(F6:F13) -> 931640000 | H14: =SUM(H6:H13) -> 522385000 | J14: =SUM(J6:J13) -> 93000000 | L14: =SUM(L6:L13) -> 316255000 | O14: =L14+J14+H14 -> 931640000
A15: 1. Urea Storage & Supply System | M15: 기존 설비 사용
A16: 1-1. Urea Storage Tank Unit
A17: 1) Urea Storage Tank | C17: 1 | D17: SET | E17: 0 | F17: =H17+J17+L17 -> 0 | G17: 0 | H17: =G17*C17 -> 0 | I17: 0 | J17: =I17*C17 -> 0 | K17: 0 | L17: =K17*C17 -> 0
A18: 2) Electric Heater | C18: 1 | D18: SET | E18: 0 | F18: =H18+J18+L18 -> 0 | G18: 0 | H18: =G18*C18 -> 0 | I18: 0 | J18: =I18*C18 -> 0 | K18: 0 | L18: =K18*C18 -> 0
A19: 3) Platform with Stair for Ammonia Storage Area | C19: 2 | D19: ton | E19: 0 | F19: =H19+J19+L19 -> 0 | G19: 0 | H19: =G19*C19 -> 0 | I19: 0 | J19: =I19*C19 -> 0 | K19: 0 | L19: =K19*C19 -> 0
A20: 소 계 | F20: =SUM(F17:F19) -> 0 | H20: =SUM(H17:H19) -> 0 | J20: =SUM(J17:J19) -> 0 | L20: =SUM(L17:L19) -> 0
A21: 합 계 | F21: =+F20 -> 0 | H21: =+H20 -> 0 | J21: =+J20 -> 0 | L21: =+L20 -> 0
A22: 2. SCR and Auxiliary System
A23: 2-1. Catalyst
A24: 1) SCR Catalyst with Module | C24: 1 | D24: LOT | E24: =F24/C24 -> 0 | F24: =H24+J24+L24 -> 0 | G24: 0 | H24: =G24*C24 -> 0 | I24: 0 | J24: =I24*C24 -> 0 | K24: 0 | L24: =K24*C24 -> 0 | M24: 기존 설비 사용
A25: 소 계 | F25: =SUM(F24:F24) -> 0 | H25: =SUM(H24:H24) -> 0 | J25: =SUM(J24:J24) -> 0 | L25: =SUM(L24:L24) -> 0
A28: 2-2. Catalyst Support Structure | C28: 1 | D28: Ton | E28: =F28/C28 -> 0 | F28: =H28+J28+L28 -> 0 | G28: 0 | H28: =G28*C28 -> 0 | I28: 0 | J28: =I28*C28 -> 0 | K28: 0 | L28: =K28*C28 -> 0 | M28: 기존 설비 사용
A29: 소 계 | F29: =F28 -> 0 | H29: =H28 -> 0 | J29: =J28 -> 0 | L29: =L28 -> 0
A30: 2-3. Monorail Hoist | C30: 1 | D30: LOT | E30: =F30/C30 -> 0 | F30: =H30+J30+L30 -> 0 | G30: 0 | H30: =G30*C30 -> 0 | I30: 0 | J30: =I30*C30 -> 0 | K30: 0 | L30: =K30*C30 -> 0 | M30: 기존 설비 사용
A31: 소 계 | F31: =F30 -> 0 | H31: =H30 -> 0 | J31: =J30 -> 0 | L31: =L30 -> 0
A32: 합 계 | F32: =F31+F29+F25 -> 0 | H32: =H31+H29+H25 -> 0 | J32: =J31+J29+J25 -> 0 | L32: =L31+L29+L25 -> 0
A33: 3. Urea Injection System
A34: 3-1. Circulation Module Skid | C34: 1 | D34: LOT
A35: 1) Urea Supply Pump | C35: 3 | D35: SET | E35: =F35/C35 -> 0 | F35: =H35+J35+L35 -> 0 | G35: 0 | H35: =G35*C35 -> 0 | I35: 0 | J35: =I35*C35 -> 0 | K35: 0 | L35: =K35*C35 -> 0 | M35: 기존 설비 사용
A36: 2) Skid Frame 제작 | C36: 1 | D36: LOT | E36: =F36/C36 -> 0 | F36: =H36+J36+L36 -> 0 | G36: 0 | H36: =G36*C36 -> 0 | I36: 0 | J36: =I36*C36 -> 0 | K36: 0 | L36: 0 | M36: 기존 설비 사용
A37: 소 계 | F37: =F36+F35 -> 0 | H37: =H36+H35 -> 0 | J37: =J36+J35 -> 0 | L37: =L36+L35 -> 0
A38: 3-2. Metering Module Skid
A39: 1) Metering Module Skid | B39: Container 구성 | C39: 2 | D39: LOT | E39: =F39/C39 -> 36000000 | F39: =H39+J39+L39 -> 72000000 | G39: 36000000 | H39: =G39*C39 -> 72000000 | I39: 0 | J39: 0 | K39: 0 | L39: =K39*C39 -> 0
A40: - Pneumatic On-off Ball Valve | B40: 40A | C40: 2 | D40: EA
A41: - Flow Transmitter | B41: 15A, Magnetic | C41: 2 | D41: EA
A42: - Flow Control Valve | B42: 15A, Magnetic | C42: 2 | D42: EA
...

Sheet 실행예산서 갑지
A1: 실 행 예 산 서
A2: 공사명 : | B2: HRSG #11, #12 SCR 환원제 직접 분사 설비 설치 공사 | Z2: 2025.09.29
A3: 결 재 | B3: 팀 장 | D3: 담 당 장 | F3: 본부장 | H3: 대표이사 | J3: 구 분 항 목 | P3: 견적보고 | R3: 실행예산 | T3: 집행예정 | V3: 증감 | X3: - | Z3: -
P4: 2025.08 | Q4: % | R4: 2025.09 | S4: % | U4: % | X4: - | Z4: - | AA4: %
P5: A | R5: B | T5: c | V5: c-B | X5: (C) | Z5: (B)-(A)
J6: 1. 제 조 원 가 | P6: =P7+P28 -> #REF! | Q6: =P$6/P$30 -> #REF! | R6: =R7+R28 -> #REF! | S6: =R6/R30 -> #REF! | T6: =T7+T28 -> #REF! | U6: =T6/T30 -> #REF! | V6: =T6-R6 -> #REF! | W6: 1 | X6: =X7+X28 -> 0 | Y6: =IFERROR(X6/X$30,0) -> 0 | AA6: =IFERROR((R6/P6)-1,0) -> 0
A7: 계 약 금 액 | B7: 공급가 | C7: =R30 -> 935530000 | F7: 계 | G7: =C7+C9 -> 1029083000 | K7: 직접원가 | P7: =SUM(P8:P10) -> #REF! | Q7: =P$7/P$30 -> #REF! | R7: =SUM(R8:R10) -> #REF! | S7: =R7/R30 -> #REF! | T7: =SUM(T8:T10) -> #REF! | U7: =T7/T30 -> #REF! | V7: =R7-P7 -> #REF! | W7: =U7-S7 -> #REF! | X7: =SUM(X8:X10) -> 0 | Y7: 0
L8: ① 재 료 비 | P8: =SUMIF(#REF!,SUBSTITUTE(SUBSTITUTE($L8,"①","")," ",""),#REF!) -> #REF! | Q8: =P8/P$30 -> #REF! | R8: =SUMIF(#REF!,SUBSTITUTE(SUBSTITUTE($L8,"①","")," ",""),#REF!) -> #REF! | S8: =IFERROR(R8/R$30,0) -> 0 | T8: =SUMIF(#REF!,SUBSTITUTE(SUBSTITUTE($L8,"①","")," ",""),#REF!) -> #REF! | U8: =IFERROR(T8/T$30,0) -> 0 | V8: =T8-R8 -> #REF! | W8: =IFERROR(V8/V$30,0) -> 0 | Y8: =IFERROR(X8/X$30,0) -> 0 | AA8: =IFERROR((R8/P8)-1,0) -> 0
B9: VAT | C9: =INT(C7*0.1) -> 93553000 | L9: ② 노 무 비 | P9: =SUMIF(#REF!,SUBSTITUTE(SUBSTITUTE($L9,"②","")," ",""),#REF!) -> #REF! | Q9: =P9/P$30 -> #REF! | R9: =SUMIF(#REF!,SUBSTITUTE(SUBSTITUTE($L9,"②","")," ",""),#REF!) -> #REF! | S9: =IFERROR(R9/R$30,0) -> 0 | T9: =SUMIF(#REF!,SUBSTITUTE(SUBSTITUTE($L9,"①","")," ",""),#REF!) -> #REF! | U9: =IFERROR(T9/T$30,0) -> 0 | V9: =T9-R9 -> #REF! | W9: =IFERROR(V9/V$30,0) -> 0 | Y9: =IFERROR(X9/X$30,0) -> 0 | AA9: =IFERROR((R9/P9)-1,0) -> 0
A10: 공 사 기 간 | B10: 시작일 | C10: - | F10: 발주처 | G10: 통영에코파워 | L10: ③ 경비 | P10: =SUM(P11:P27) -> #REF! | Q10: =P10/P$30 -> #REF! | R10: =SUM(R11:R27) -> #REF! | S10: =IFERROR(R10/R$30,0) -> 0 | T10: =SUM(T11:T27) -> #REF! | U10: =IFERROR(T10/T$30,0) -> 0 | V10: =T10-R10 -> #REF! | W10: =U10-S10 -> 0 | X10: =SUM(X11:X27) -> 0 | Y10: =IFERROR(X10/X$30,0) -> 0 | AA10: =IFERROR((R10/P10)-1,0) -> 0
B11: 종료일 | C11: 2026.04.15 | F11: 현 장 | G11: 경남 통영 | M11: 외주가공비-설비(도급) | P11: =SUMIF(#REF!,'실행예산서 갑지'!$M11,#REF!) -> #REF! | Q11: =P11/P$30 -> #REF! | R11: =SUMIF(#REF!,'실행예산서 갑지'!$M11,#REF!) -> #REF! | S11: =IFERROR(R11/R$30,0) -> 0 | T11: =SUMIF(#REF!,'실행예산서 갑지'!$M11,#REF!) -> #REF! | U11: =IFERROR(T11/T$30,0) -> 0 | V11: =T11-R11 -> #REF! | W11: =U11-S11 -> 0 | Y11: =IFERROR(X11/X$30,0) -> 0 | AA11: =IFERROR((R11/P11)-1,0) -> 0
A12: 실행예산 (제조원가) | B12: 최초 | C12: =P6 -> #REF! | F12: 실행율 (제조원가) | G12: 최초 | H12: =Q6 -> #REF! | M12: 외주용역비-도급 | P12: =SUMIF(#REF!,'실행예산서 갑지'!$M12,#REF!) -> #REF! | Q12: =P12/P$30 -> #REF! | R12: =SUMIF(#REF!,'실행예산서 갑지'!$M12,#REF!) -> #REF! | S12: =IFERROR(R12/R$30,0) -> 0 | T12: =SUMIF(#REF!,'실행예산서 갑지'!$M12,#REF!) -> #REF! | U12: =IFERROR(T12/T$30,0) -> 0 | V12: =T12-R12 -> #REF! | W12: =U12-S12 -> 0 | Y12: =IFERROR(X12/X$30,0) -> 0 | AA12: =IFERROR((R12/P12)-1,0) -> 0
B13: 1차 변경 | C13: =R6 -> #REF! | G13: 1차 변경 | H13: =S6 -> #REF! | M13: 운반비-국내 | P13: =SUMIF(#REF!,'실행예산서 갑지'!$M13,#REF!) -> #REF! | Q13: =P13/P$30 -> #REF! | R13: =SUMIF(#REF!,'실행예산서 갑지'!$M13,#REF!) -> #REF! | S13: =IFERROR(R13/R$30,0) -> 0 | T13: =SUMIF(#REF!,'실행예산서 갑지'!$M13,#REF!) -> #REF! | U13: =IFERROR(T13/T$30,0) -> 0 | V13: =T13-R13 -> #REF! | W13: =U13-S13 -> 0 | Y13: =IFERROR(X13/X$30,0) -> 0 | AA13: =IFERROR((R13/P13)-1,0) -> 0
B14: 2차 변경 | C14: 0 | G14: 2차 변경 | H14: 0 | M14: 소모품비-기타 | P14: =SUMIF(#REF!,'실행예산서 갑지'!$M14,#REF!) -> #REF! | Q14: =P14/P$30 -> #REF! | R14: =SUMIF(#REF!,'실행예산서 갑지'!$M14,#REF!) -> #REF! | S14: =IFERROR(R14/R$30,0) -> 0 | T14: =SUMIF(#REF!,'실행예산서 갑지'!$M14,#REF!) -> #REF! | U14: =IFERROR(T14/T$30,0) -> 0 | V14: =T14-R14 -> #REF! | W14: =U14-S14 -> 0 | Y14: =IFERROR(X14/X$30,0) -> 0 | AA14: =IFERROR((R14/P14)-1,0) -> 0
B15: 3차 변경 | C15: 0 | G15: 3차 변경 | H15: 0 | M15: 소모품비-안전용품 | P15: =SUMIF(#REF!,'실행예산서 갑지'!$M15,#REF!) -> #REF! | Q15: =P15/P$30 -> #REF! | R15: =SUMIF(#REF!,'실행예산서 갑지'!$M15,#REF!) -> #REF! | S15: =IFERROR(R15/R$30,0) -> 0 | T15: =SUMIF(#REF!,'실행예산서 갑지'!$M15,#REF!) -> #REF! | U15: =IFERROR(T15/T$30,0) -> 0 | V15: =T15-R15 -> #REF! | W15: =U15-S15 -> 0 | Y15: =IFERROR(X15/X$30,0) -> 0 | AA15: =IFERROR((R15/P15)-1,0) -> 0
B16: 정산 | G16: 정산 | M16: 여비교통비-국내 | P16: =SUMIF(#REF!,'실행예산서 갑지'!$M16,#REF!) -> #REF! | Q16: =P16/P$30 -> #REF! | R16: =SUMIF(#REF!,'실행예산서 갑지'!$M16,#REF!) -> #REF! | S16: =IFERROR(R16/R$30,0) -> 0 | T16: =SUMIF(#REF!,'실행예산서 갑지'!$M16,#REF!) -> #REF! | U16: =IFERROR(T16/T$30,0) -> 0 | V16: =T16-R16 -> #REF! | W16: =U16-S16 -> 0 | Y16: =IFERROR(X16/X$30,0) -> 0 | AA16: =IFERROR((R16/P16)-1,0) -> 0
A17: 대금조건 | B17: 선급금 : 10% (계산서 발행 후 당월 현금지급) | M17: 보험료-보증 | P17: =SUMIF(#REF!,'실행예산서 갑지'!$M17,#REF!) -> #REF! | Q17: =P17/P$30 -> #REF! | R17: =SUMIF(#REF!,'실행예산서 갑지'!$M17,#REF!) -> #REF! | S17: =IFERROR(R17/R$30,0) -> 0 | T17: =SUMIF(#REF!,'실행예산서 갑지'!$M17,#REF!) -> #REF! | U17: =IFERROR(T17/T$30,0) -> 0 | V17: =T17-R17 -> #REF! | W17: =U17-S17 -> 0 | Y17: =IFERROR(X17/X$30,0) -> 0 | AA17: =IFERROR((R17/P17)-1,0) -> 0
B18: 중도금 : 80% (계산서 발행 후 당월 현금지급) | M18: 사택관리비 | P18: =SUMIF(#REF!,'실행예산서 갑지'!$M18,#REF!) -> #REF! | Q18: =P18/P$30 -> #REF! | R18: =SUMIF(#REF!,'실행예산서 갑지'!$M18,#REF!) -> #REF! | S18: =IFERROR(R18/R$30,0) -> 0 | T18: =SUMIF(#REF!,'실행예산서 갑지'!$M18,#REF!) -> #REF! | U18: =IFERROR(T18/T$30,0) -> 0 | V18: =T18-R18 -> #REF! | W18: =U18-S18 -> 0 | Y18: =IFERROR(X18/X$30,0) -> 0 | AA18: =IFERROR((R18/P18)-1,0) -> 0
B19: 잔금 : 10% (계산서 발행 후 당월 현금지급) | M19: 잡급 | P19: =SUMIF(#REF!,'실행예산서 갑지'!$M19,#REF!) -> #REF! | Q19: =P19/P$30 -> #REF! | R19: =SUMIF(#REF!,'실행예산서 갑지'!$M19,#REF!) -> #REF! | S19: =IFERROR(R19/R$30,0) -> 0 | T19: =SUMIF(#REF!,'실행예산서 갑지'!$M19,#REF!) -> #REF! | U19: =IFERROR(T19/T$30,0) -> 0 | V19: =T19-R19 -> #REF! | W19: =U19-S19 -> 0 | Y19: =IFERROR(X19/X$30,0) -> 0 | AA19: =IFERROR((R19/P19)-1,0) -> 0
B20: 지급 조건의 경우 일반적인 사항이며, 최종 계약시 확정 예정임. | M20: 지급수수료-기타 | P20: =SUMIF(#REF!,'실행예산서 갑지'!$M20,#REF!) -> #REF! | Q20: =P20/P$30 -> #REF! | R20: =SUMIF(#REF!,'실행예산서 갑지'!$M20,#REF!) -> #REF! | S20: =IFERROR(R20/R$30,0) -> 0 | T20: =SUMIF(#REF!,'실행예산서 갑지'!$M20,#REF!) -> #REF! | U20: =IFERROR(T20/T$30,0) -> 0 | V20: =T20-R20 -> #REF! | W20: =U20-S20 -> 0 | Y20: =IFERROR(X20/X$30,0) -> 0 | AA20: =IFERROR((R20/P20)-1,0) -> 0
A21: 보 증 서 | B21: 계약금보증증권 : 계약금액의 10% | M21: 지급임차료-지게차 | P21: =SUMIF(#REF!,'실행예산서 갑지'!$M21,#REF!) -> #REF! | Q21: =P21/P$30 -> #REF! | R21: =SUMIF(#REF!,'실행예산서 갑지'!$M21,#REF!) -> #REF! | S21: =IFERROR(R21/R$30,0) -> 0 | T21: =SUMIF(#REF!,'실행예산서 갑지'!$M21,#REF!) -> #REF! | U21: =IFERROR(T21/T$30,0) -> 0 | V21: =T21-R21 -> #REF! | W21: =U21-S21 -> 0 | Y21: =IFERROR(X21/X$30,0) -> 0 | AA21: =IFERROR((R21/P21)-1,0) -> 0
B22: 선급금보증증권 : 계약금액의 10% | M22: 지급임차료-기타 | P22: =SUMIF(#REF!,'실행예산서 갑지'!$M22,#REF!) -> #REF! | Q22: =P22/P$30 -> #REF! | R22: =SUMIF(#REF!,'실행예산서 갑지'!$M22,#REF!) -> #REF! | S22: =IFERROR(R22/R$30,0) -> 0 | T22: =SUMIF(#REF!,'실행예산서 갑지'!$M22,#REF!) -> #REF! | U22: =IFERROR(T22/T$30,0) -> 0 | V22: =T22-R22 -> #REF! | W22: =U22-S22 -> 0 | Y22: =IFERROR(X22/X$30,0) -> 0 | AA22: =IFERROR((R22/P22)-1,0) -> 0
B23: 하자이행보증금 : 계약금의 10% (하자이행기간 : 성능시험 합격 후 준공일로부터 3년) | M23: 차량유지비-수선비_법인차량 | P23: =SUMIF(#REF!,'실행예산서 갑지'!$M23,#REF!) -> #REF! | Q23: =P23/P$30 -> #REF! | R23: =SUMIF(#REF!,'실행예산서 갑지'!$M23,#REF!) -> #REF! | S23: =IFERROR(R23/R$30,0) -> 0 | T23: =SUMIF(#REF!,'실행예산서 갑지'!$M23,#REF!) -> #REF! | U23: =IFERROR(T23/T$30,0) -> 0 | V23: =T23-R23 -> #REF! | W23: =U23-S23 -> 0 | Y23: =IFERROR(X23/X$30,0) -> 0 | AA23: =IFERROR((R23/P23)-1,0) -> 0
B24: 지체상금 : 지체 1일당 도급 금액의 1/1000 | M24: 차량유지비-유류대_법인차량 | P24: =SUMIF(#REF!,'실행예산서 갑지'!$M24,#REF!) -> #REF! | Q24: =P24/P$30 -> #REF! | R24: =SUMIF(#REF!,'실행예산서 갑지'!$M24,#REF!) -> #REF! | S24: =IFERROR(R24/R$30,0) -> 0 | T24: =SUMIF(#REF!,'실행예산서 갑지'!$M24,#REF!) -> #REF! | U24: =IFERROR(T24/T$30,0) -> 0 | V24: =T24-R24 -> #REF! | W24: =U24-S24 -> 0 | Y24: =IFERROR(X24/X$30,0) -> 0 | AA24: =IFERROR((R24/P24)-1,0) -> 0
A25: 공 사 개 요 | B25: 기존 UREA 열분해 설비를 이용한 탈질설비를 보유하고 있었으나, 운전 중 주기적인 | M25: 차량유지비-기타_법인차량 | P25: =SUMIF(#REF!,'실행예산서 갑지'!$M25,#REF!) -> #REF! | Q25: =P25/P$30 -> #REF! | R25: =SUMIF(#REF!,'실행예산서 갑지'!$M25,#REF!) -> #REF! | S25: =IFERROR(R25/R$30,0) -> 0 | T25: =SUMIF(#REF!,'실행예산서 갑지'!$M25,#REF!) -> #REF! | U25: =IFERROR(T25/T$30,0) -> 0 | V25: =T25-R25 -> #REF! | W25: =U25-S25 -> 0 | Y25: =IFERROR(X25/X$30,0) -> 0 | AA25: =IFERROR((R25/P25)-1,0) -> 0
B26: founling 현상 등으로 인해 발전소 S/D가 잦아짐에 따라 개선된 당사의 직접 분사 설비로 | M26: 복리후생비-업무추진비 | P26: =SUMIF(#REF!,'실행예산서 갑지'!$M26,#REF!) -> #REF! | Q26: =P26/P$30 -> #REF! | R26: =SUMIF(#REF!,'실행예산서 갑지'!$M26,#REF!) -> #REF! | S26: =IFERROR(R26/R$30,0) -> 0 | T26: =SUMIF(#REF!,'실행예산서 갑지'!$M26,#REF!) -> #REF! | U26: =IFERROR(T26/T$30,0) -> 0 | V26: =T26-R26 -> #REF! | W26: =U26-S26 -> 0 | Y26: =IFERROR(X26/X$30,0) -> 0 | AA26: =IFERROR((R26/P26)-1,0) -> 0
B27: 교체하여 발전소 운전이 정상운전 되도록 탈질 설비를 개선하는 공사임. | M27: 예비비 | P27: =SUMIF(#REF!,'실행예산서 갑지'!$M27,#REF!) -> #REF! | Q27: =P27/P$30 -> #REF! | R27: =SUMIF(#REF!,'실행예산서 갑지'!$M27,#REF!) -> #REF! | S27: =IFERROR(R27/R$30,0) -> 0 | T27: =SUMIF(#REF!,'실행예산서 갑지'!$M27,#REF!) -> #REF! | U27: =IFERROR(T27/T$30,0) -> 0 | V27: =T27-R27 -> #REF! | W27: =U27-S27 -> 0 | Y27: =IFERROR(X27/X$30,0) -> 0 | AA27: =IFERROR((R27/P27)-1,0) -> 0
A28: 특 기 사 항 | B28: 1. 성능보증 사항 - Nox: 4ppm / NH3 Slip : 5ppm 2. Tie-In 공사의 경우 S/D 기간에 완료 (일정은 추석 연휴 10/6~10 예정. 현설 자료) 3. 인허가 제외. 4. 토목공사 제외. | K28: 제조간접비 | P28: =P$30*Q$28 -> 49450000 | Q28: 0.043 | R28: =#REF! -> #REF! | S28: =IFERROR(R28/R$30,0) -> 0 | T28: =#REF! -> #REF! | U28: =IFERROR(T28/T$30,0) -> 0 | V28: =T28-R28 -> #REF! | W28: =U28-S28 -> 0 | Y28: =IFERROR(X28/X$30,0) -> 0 | AA28: =IFERROR((R28/P28)-1,0) -> 0
J29: 2. 매 출 이 익 | P29: =P30-P6 -> #REF! | Q29: =P29/P$30 -> #REF! | R29: =R30-R6 -> #REF! | S29: =IFERROR(R29/R$30,0) -> 0 | T29: =T30-T6 -> #REF! | U29: =IFERROR(T29/T$30,0) -> 0 | V29: =T29-R29 -> #REF! | W29: =U29-S29 -> 0 | X29: =X30-X6 -> 0 | Y29: =IFERROR(X29/X$30,0) -> 0 | AA29: =S29-Q29 -> #REF!
J30: 3. 계 약 금 액 | P30: 1150000000 | Q30: =P30/P$30 -> 1 | R30: 935530000 | S30: =IFERROR(R30/R$30,0) -> 1 | T30: 935530000 | U30: =IFERROR(T30/T$30,0) -> 1 | V30: =T30-R30 -> 0 | W30: =U30-S30 -> 0 | X30: 0 | Y30: =IFERROR(X30/X$30,0) -> 0 | AA30: =S30-Q30 -> 0
J31: 4. 판 관 비 | P31: =P30*Q31 -> 102350000 | Q31: 0.089 | R31: 0 | S31: 0 | T31: 0 | U31: 0 | V31: =T31-R31 -> 0 | W31: =U31-S31 -> 0 | X31: =X30*Y31 -> 0 | Y31: 0.089 | AA31: =S31-Q31 -> -0.089
J32: 5. 영 업 이 익 | P32: =P29-P31 -> #REF! | Q32: =P32/P$30 -> #REF! | R32: =R29-R31 -> #REF! | S32: 0 | T32: =T29-T31 -> #REF! | U32: 0 | V32: =T32-R32 -> #REF! | W32: =U32-S32 -> 0 | X32: =X29-X31 -> 0 | AA32: =S32-Q32 -> #REF!
AD33: 구분 | AE33: 계약금액 | AH33: 제조원가 | AI33: 판관비(8.9%) | AJ33: 영업이익
AF34: 직접원가 | AG34: 제조간접비(4.3%)
AD35: 기존 | AE35: 1150000000 | AF35: 998200000 | AG35: =AE35*4.3% -> 49450000 | AH35: =AF35+AG35 -> 1047650000 | AI35: =AE35*8.9% -> 1.0235e+08 | AJ35: =AE35-AH35-AI35 -> 0
AD36: 변경 | AE36: 9.3553e+08 | AF36: 995626360 | AG36: =AE36*4.3% -> 40227790 | AH36: =AF36+AG36 -> 1035854150 | AI36: =AE36*8.9% -> 83262170 | AJ36: =AE36-AH36-AI36 -> -1.8358632e+08
AD37: *직접원가 : 예비비 포함 (계약금액의 1.2%)

Sheet 협력업체 기성금신청 1안
B1: 폰트 : 10, 본문 행 높이 :20, 구분 라인 행 높이 : 15, 박스기준은 "2.결제조건"사이즈 기준으로 좌우 대칭 맞출것
A2: 1 | B2: 1 | C2: 1 | D2: 1 | E2: 1 | F2: 1 | G2: 1 | H2: 1 | I2: 1 | J2: 1 | K2: 1 | L2: 1 | M2: 1 | N2: 1 | O2: 1 | P2: 1 | Q2: 1 | R2: 1 | S2: 1 | T2: 1 | U2: 1 | V2: 1 | W2: 1 | X2: 1 | Y2: 1 | Z2: 1 | AA2: 1 | AB2: 1 | AC2: 1 | AD2: 1 | AE2: 1 | AF2: 1 | AG2: 1 | AH2: 1 | AI2: 1 | AJ2: 1 | AK2: 1 | AL2: 1 | AM2: 1 | AN2: 1 | AO2: 1 | AP2: 1 | AQ2: 1 | AR2: 1 | AS2: 1 | AT2: 1 | AU2: 1 | AV2: 1 | AW2: 1 | AX2: 1 | AY2: 1 | AZ2: 1 | BA2: 1 | BB2: 1 | BC2: 1 | BD2: 1 | BE2: 1 | BF2: 1 | BG2: 1 | BH2: 1 | BI2: 1 | BJ2: 1 | BK2: 1 | BL2: 1 | BM2: 1
B3: 통영에코파워 프로젝트 관련하여 협력업체 기성금 지급을 아래와 같이 지급하고자 하오니 재가하여
B4: 주시기 바랍니다.
B5: - 아 래 -
B7: 1. 프로젝트 명 : 통영에코파워 / HRSG#11, #12 SCR 환원제 직접 분사 설비 설치 공사
B8: 2. 수주금액/프로젝트 코드 : 935,530,000원 / PASC0IT20250011
B9: 3. 협력업체 기성금 신청내역 | BC9: (단위: 원 VAT 별도)
C10: 업체명 | O10: 계약품목 | Z10: 발주금액 | AJ10: 금회기성 | AT10: 누계기성 | BD10: 잔여기성
C11: 주영씨엔에스 | O11: Auto Valve | Z11: 61000000 | AJ11: 6100000 | AT11: 61000000 | BD11: -
Z12: 1 | AJ12: =AJ11/Z11 -> 0.1 | AT12: =AT11/Z11 -> 1 | BD12: 0
C13: 한국요꼬가와전기 | O13: Instrument | Z13: 69000000 | AJ13: 6900000 | AT13: 69000000 | BD13: -
Z14: 1 | AJ14: =AJ13/Z13 -> 0.1 | AT14: =AT13/Z13 -> 1 | BD14: 0
C15: 미래종합기술 | O15: 배관 ISO 작성 외 | Z15: 8800000 | AJ15: 8800000 | AT15: 8800000 | BD15: -
Z16: 1 | AJ16: =AJ15/Z15 -> 1 | AT16: =AT15/Z15 -> 1 | BD16: 0
B18: 4. 기타사항
B19: 1) 계정 코드 및 코스트센터 : 외주가공비-설비(도급) 외 / 플랜트대기파트
B20: 2) 공정 진행률에 따른 기성금 지급
B22: 5. 프로젝트 비용현황 | AX22: (단위: 원 VAT 별도)
C23: 업체명 | O23: 계약품목 | Z23: 발주금액 | AJ23: 금회 | AT23: 전월 누계 | BD23: 잔여 | BN23: 계약일 | BO23: 종료일 | BP23: 착공일 | BQ23: 준공일 | BR23: 업체명 | BS23: 비고
E24: 에스에이치씨 | O24: Module 제작 | Z24: 71000000 | AJ24: 49700000 | AT24: 14200000 | BD24: =Z24-AJ24-AT24 -> 7100000
E25: 미래종합기술 | O25: 기계,배관 설치 | Z25: 235000000 | AJ25: 70500000 | AT25: 117500000 | BD25: =Z25-AJ25-AT25 -> 47000000
E26: 주영씨엔에스 | O26: Auto Valves | Z26: 61000000 | AJ26: 6100000 | AT26: 54900000 | BD26: =Z26-AJ26-AT26 -> 0
E27: 한국요꼬가와 | O27: Instruments 1차 | Z27: 69000000 | BD27: =Z27-AJ27-AT27 -> 69000000
E28: 대청테크놀로지 | O28: PDP Panel | Z28: 33000000 | BD28: =Z28-AJ28-AT28 -> 33000000
E29: 대청테크놀로지 | O29: 전기계장 설치 | Z29: 141000000 | BD29: =Z29-AJ29-AT29 -> 141000000
E30: 한국에머슨 | O30: DCS Modification | Z30: 35500000 | BD30: =Z30-AJ30-AT30 -> 35500000
C31: 외주가공비-설비(도급) 합계 | Z31: =SUM(Z24:AI30) -> 645500000 | AJ31: =SUM(AJ24:AS30) -> 126300000 | AT31: =SUM(AT24:BC30) -> 186600000 | BD31: =SUM(BD24:BM30) -> 332600000
E32: 기계설계 등 | O32: 미래종합기술 | Z32: 8800000
E33: CFD | O33: 성균관대학교 | Z33: 17000000
C34: 외주용역비-도급 합계 | Z34: =SUM(Z32:AI33) -> 25800000 | AJ34: =SUM(AJ32:AS33) -> 0 | AT34: =SUM(AT32:BC33) -> 0 | BD34: =SUM(BD32:BM33) -> 0
C35: 여비교통비
C36: 차량유지비-수선비-법인차량
C37: 소모품비-안전용품
C38: 지급수수료-기타
C39: 보험료-보증
C40: 지급수수료-기타
C41: 1월 마감기준 합계
B43: 6. 자금수지 현황 | BC43: (단위: 원 VAT 별도)
C44: 구분 | O44: 고객사 기성금(A) | AA44: 지출(B) | AM44: 차이(A-B) | AY44: 비고
...
